Workbook

Sheet semantics_nouns
A1: lemma_kek | B1: countability_kek | C1: gloss_en | D1: gloss_en_f | E1: countability_en | F1: gloss_es | G1: gloss_es_f | H1: gender_es | I1: countability_es | J1: class | K1: loan | L1: notes | M1: p_weight | N1: p_debug_percent
A2: polem | B2: count | C2: abandoned house | E2: count | F2: casa abandonada | H2: f | I2: count | J2: building | K2: FALSE | M2: 7025.329 | N2: 2.5914783
A3: aj ajlanel | B3: count | C3: accountant | E3: count | F3: contador | G3: contadora | H3: m | I3: count | J3: occupation | K3: FALSE | M3: 443.26829 | N3: 0.16351123
A4: saaj poyanam | B4: count | C4: adolescent | E4: count | F4: adolescente | H4: m | I4: count | J4: human | K4: FALSE
A5: saaj al | B5: count | C5: adolescent boy | E5: count | F5: niño adolescente | H5: m | I5: count | J5: human | K5: FALSE
A6: saaj ixqa'al | B6: count | C6: adolescent girl | E6: count | F6: niña adolescente | H6: f | I6: count | J6: human | K6: FALSE
A7: nimla poyanam | B7: count | C7: adult | E7: count | F7: adulto | G7: adulta | H7: m | I7: count | J7: human | K7: FALSE
A8: ik'e | B8: count | C8: agave plant | E8: count | F8: maguey | H8: m | I8: count | J8: plant | K8: FALSE | M8: 1819.7009 | N8: 0.67124476
A9: lotz | B9: mass | C9: agua ardiente | E9: mass | F9: agua ardiente | H9: f | I9: mass | J9: beverage | K9: FALSE | L9: a distilled alcoholic spirit | M9: 4570.8819 | N9: 1.6860906
A10: ha' na'kaltesin | B10: mass | C10: alcohol | E10: mass | F10: alcohol | H10: m | I10: mass | J10: beverage | K10: FALSE | L10: alcohol (beverage) | M10: 1183.9499 | N10: 0.43673122
A11: ahin | B11: count | C11: alligator | E11: count | F11: lagarto | H11: m | I11: count | J11: animal_wild | K11: FALSE | M11: 179.19807 | N11: 0.066101945
A12: artal | B12: count | C12: altar | E12: count | F12: altar | H12: m | I12: count | J12: artifact | K12: TRUE | M12: 493.55247 | N12: 0.18205987
A13: sank | B13: count | C13: ant | E13: count | F13: hormiga | H13: f | I13: count | J13: insect | K13: FALSE | M13: 374.39784 | N13: 0.13810654
A14: tz'uq'tz'un | B14: count | C14: anteater | E14: count | F14: tamandúa | H14: f | I14: count | J14: animal_wild | K14: FALSE | M14: 33.113112 | N14: 0.012214647
A15: misik | B15: count | C15: antenna | E15: count | F15: antena | H15: f | I15: count | J15: body_part | K15: FALSE | L15: insect antenna
A16: yupus | B16: count | C16: anus | E16: count | F16: ano | H16: m | I16: count | J16: body_part | K16: FALSE | M16: 357.54716 | N16: 0.13189072
A17: aj yoob'ahom kab'l | B17: count | C17: architect | E17: count | F17: arquitecto | G17: arquitecta | H17: m | I17: count | J17: occupation | K17: FALSE | M17: 524.80746 | N17: 0.1935891
A18: tel | B18: count | C18: arm | E18: count | F18: brazo | H18: m | I18: count | J18: body_part | K18: FALSE | M18: 1423.4209 | N18: 0.52506641
A19: ib'oy | B19: count | C19: armadillo | E19: count | F19: cusuco | H19: m | I19: count | J19: animal_wild | K19: FALSE | L19: from Nahuatl | M19: 63.095734 | N19: 0.023274529
A20: seel xul | B20: count | C20: armadillo | E20: count | F20: cusuco | H20: m | I20: count | J20: animal_wild | K20: FALSE | L20: from Nahuatl | M20: 63.095734 | N20: 0.023274529
A21: aj yoob'anel | B21: count | C21: artist | E21: count | F21: artista | H21: m | I21: count | J21: occupation | K21: FALSE | M21: 1584.8932 | N21: 0.58462974
A22: ch'amb'ul | B22: mass | C22: atol xuco | E22: mass | F22: atol xuco | H22: m | I22: mass | J22: beverage | K22: FALSE | L22: a corn-based drink, thick and usually containing, salt, chili pepper, and black bean | M22: 21.544347 | N22: 0.0079472018
A23: aj nawol chaq'rab' | B23: count | C23: attorney | E23: count | F23: abogado | G23: abogada | H23: m | I23: count | J23: occupation | K23: FALSE | M23: 1513.5612 | N23: 0.55831707
A24: ikan na' | B24: count | C24: aunt | E24: count | F24: tía | H24: f | I24: count | J24: kinship | K24: FALSE | M24: 794.32823 | N24: 0.29300896
A25: o | B25: count | C25: avocado | E25: count | F25: aguacate | H25: m | I25: count | J25: fruit | K25: FALSE
A26: maal | B26: count | C26: axe | E26: count | F26: hacha | H26: f | I26: count | J26: tool | K26: FALSE | M26: 336.25339 | N26: 0.12403595
A27: k'uula'al | B27: count | C27: baby | E27: count | F27: bebé | H27: m | I27: count | J27: human | K27: FALSE
A28: ix | B28: count | C28: back | E28: count | F28: espalda | H28: f | I28: count | J28: body_part | K28: FALSE | M28: 10633.266 | N28: 3.9223611
A29: xalb'ek | B29: count | C29: bag | E29: count | F29: bolsa | H29: f | I29: count | J29: container | K29: FALSE
A30: simb' | B30: mass | C30: bamboo | E30: mass | F30: bambú | H30: m | I30: mass | J30: plant | K30: FALSE | M30: 271.22726 | N30: 0.10004934
A31: tul | B31: count | C31: banana | E31: count | F31: plátano | H31: m | I31: count | J31: fruit | K31: FALSE | M31: 464.15888 | N31: 0.17121727
A32: yach’ | B32: count | C32: band | E32: count | F32: banda | H32: f | I32: count | K32: FALSE | L32: a band to tie with
A33: aj b'esol ismal | B33: count | C33: barber | E33: count | F33: peluquero | G33: peluquera | H33: m | I33: count | J33: occupation | K33: FALSE | M33: 346.73685 | N33: 0.12790305
A34: kachuuch' | B34: count | C34: baseball cap | E34: count | F34: gorra | H34: f | I34: count | J34: clothing | K34: FALSE | M34: 1063.3266 | N34: 0.39223611
A35: chakach | B35: count | C35: basket | E35: count | F35: canasta | H35: f | I35: count | J35: container | K35: FALSE | M35: 516.81289 | N35: 0.19064009
A36: ch'ok'oj | B36: count | C36: bat | E36: count | F36: murciélago | H36: m | I36: count | J36: animal_wild | K36: FALSE | M36: 735.64225 | N36: 0.27136109
A37: sotz' | B37: count | C37: bat | E37: count | F37: murciélago | H37: m | I37: count | J37: animal_wild | K37: FALSE | M37: 735.64225 | N37: 0.27136109
A38: tz'amb'a | B38: count | C38: beam | E38: count | F38: viga | H38: f | I38: count | J38: wood | K38: FALSE | L38: wooden beam | M38: 575.43994 | N38: 0.21226623
A39: k'ab'el | B39: mass | C39: bean soup | E39: mass | F39: sopa de frijoles | H39: f | I39: mass | J39: food | K39: FALSE | M39: 584.34141 | N39: 0.21554977
A40: xut' | B40: count | C40: bean tamale | E40: count | F40: tamalito de frijol | H40: m | I40: count | J40: food | K40: FALSE | M40: 450.12521 | N40: 0.16604058
...

Sheet to add
A1: lemma_kek | B1: countability_kek | C1: gloss_en | D1: countability_en | E1: gloss_es | F1: gloss_es_f | G1: gender_es | H1: countability_es | I1: class | J1: loan | K1: notes
A2: aj chupul xam | C2: firefighter | E2: bombero | F2: bombera
A3: aj t'anol che' | C3: logger | E3: leñador | F3: leñadora
A4: aj yiib'ahom ch'iich' | C4: mechanic | E4: mecánico | F4: mecánica
C5: pilot | E5: piloto | F5: piloto
C6: psychologist | E6: psicólogo | F6: psicóloga
C7: social worker | E7: trabajador social | F7: trabajadora social
C8: soldier | E8: soldado | F8: soldado
C9: translator | E9: traductor | F9: traductora
C10: writer | E10: =LOWER(_xlfn.TRANSLATE(C10,"en","es")) -> escritor

Sheet Allowed_classes
A1: class
A2: animal_domesticated
A3: animal_wild
A4: artifact
A5: beverage
A6: body_part
A7: building
A8: clothing
A9: container
A10: corn
A11: emotion
A12: event
... A27: wood

Sheet Classes_count
A1: class
A2: animal_domesticated | B2: =COUNTIF(semantics_nouns!J:J,Classes_count!A2) -> 14
A3: animal_wild | B3: =COUNTIF(semantics_nouns!J:J,Classes_count!A3) -> 71
A4: artifact | B4: =COUNTIF(semantics_nouns!J:J,Classes_count!A4) -> 5
A5: beverage | B5: =COUNTIF(semantics_nouns!J:J,Classes_count!A5) -> 6
A6: body_part | B6: =COUNTIF(semantics_nouns!J:J,Classes_count!A6) -> 35
A7: building | B7: =COUNTIF(semantics_nouns!J:J,Classes_count!A7) -> 3
A8: clothing | B8: =COUNTIF(semantics_nouns!J:J,Classes_count!A8) -> 13
A9: container | B9: =COUNTIF(semantics_nouns!J:J,Classes_count!A9) -> 4
A10: corn | B10: =COUNTIF(semantics_nouns!J:J,Classes_count!A10) -> 4
A11: emotion | B11: =COUNTIF(semantics_nouns!J:J,Classes_count!A11) -> 5
A12: food | B12: =COUNTIF(semantics_nouns!J:J,Classes_count!A12) -> 22
A13: fruit | B13: =COUNTIF(semantics_nouns!J:J,Classes_count!A13) -> 13
... A26: wood | B26: =COUNTIF(semantics_nouns!J:J,Classes_count!A26) -> 3
