Workbook

Sheet kek_templates
A1: id | B1: kek | C1: en | D1: es | E1: description | F1: Subject | G1: Transitivity | H1: Tense | I1: Aspect | J1: Mood | K1: Voice | L1: Polarity | M1: Q/S/C | N1: Modifier | O1: example_en | P1: p_value | Q1: variant_dist | R1: p_value_norm
A2: 1 | B2: {OCCUPATION}{AFFIX_PRONOUN}. | C2: {SUBJ_PRONOUN_EN} {BE_EN} {OCCUPATION_EN}. | D2: {SUBJ_PRONOUN_ES} {COP_ES} {OCCUPATION_ES}. | E2: Pronoun with occupation | F2: 1sg | G2: 1-cop | H2: PRS | I2: Simple | K2: Active | L2: aff | M2: Statement | N2: Is occupation | O2: I am a fireman | P2: 0.0041651584 | Q2: 0.125 | R2: 0.00038263041
A3: 2 | B3: {ADJ}{AFFIX_PRONOUN}. | C3: {SUBJ_PRONOUN_EN} {BE_EN} {ADJ_EN}. | D3: {SUBJ_PRONOUN_ES} {COP_ES} {ADJ_ES}. | E3: Pronoun with attribute | F3: 1sg | G3: 1-cop | H3: PRS | I3: Simple | K3: Active | L3: aff | M3: Statement | N3: None | O3: I am big | P3: 0.0041651584 | Q3: 0.5 | R3: 0.0015305216
A4: 3 | B4: {PRED_NP}{AFFIX_PRONOUN}. | C4: {SUBJ_PRONOUN_EN} {BE_EN} {PRED_NP_EN}. | D4: {SUBJ_PRONOUN_ES} {V_SER_ES} {PRED_NP_ES}. | E4: Noun in stative sentence | F4: 1sg | G4: 1-cop | H4: PRS | I4: Simple | K4: Active | L4: aff | M4: Statement | N4: None | O4: I am a boy | P4: 0.0041651584 | Q4: 0.5 | R4: 0.0015305216
A5: 4 | B5: {ADJ}{AFFIX_PRONOUN}. | C5: {SUBJ_PRONOUN_EN} {BE_EN} {ADJ_EN}. | D5: {SUBJ_PRONOUN_ES} {COP_ES} {ADJ_ES}. | E5: Pronoun with attribute | F5: 1pl | G5: 1-cop | H5: PRS | I5: Simple | K5: Active | L5: aff | M5: Statement | N5: None | O5: We are big | P5: 0.0023429016 | Q5: 1 | R5: 0.0017218369
A6: 5 | B6: {OCCUPATION}{AFFIX_PRONOUN}. | C6: {SUBJ_PRONOUN_EN} {BE_EN} {OCCUPATION_EN}. | D6: {SUBJ_PRONOUN_ES} {COP_ES} {OCCUPATION_ES}. | E6: Pronoun with occupation | F6: 2sg | G6: 1-cop | H6: PRS | I6: Simple | K6: Active | L6: aff | M6: Statement | N6: Is occupation | O6: You are a chef | P6: 0.0035971823 | Q6: 0.25 | R6: 0.00066090707
A7: 6 | B7: {ADJ}{AFFIX_PRONOUN}. | C7: {SUBJ_PRONOUN_EN} {BE_EN} {ADJ_EN}. | D7: {SUBJ_PRONOUN_ES} {COP_ES} {ADJ_ES}. | E7: Pronoun with attribute | F7: 2sg | G7: 1-cop | H7: PRS | I7: Simple | K7: Active | L7: aff | M7: Statement | N7: None | O7: You are big | P7: 0.0035971823 | Q7: 1 | R7: 0.0026436283
A8: 7 | B8: {OCCUPATION}{AFFIX_PRONOUN} {SUBJ_PRONOUN}. | C8: {SUBJ_PRONOUN_EN} {BE_EN} {OCCUPATION_EN}. | D8: {SUBJ_PRONOUN_ES} {COP_ES} {OCCUPATION_ES}. | E8: Pronoun with occupation | F8: 3sg | G8: 1-cop | H8: PRS | I8: Simple | K8: Active | L8: aff | M8: Statement | N8: Is occupation | O8: She is a fireman | P8: 0.0027925494 | Q8: 0.25 | R8: 0.0005130726
A9: 8 | B9: {ADJ}{AFFIX_PRONOUN}. | C9: {SUBJ_PRONOUN_EN} {BE_EN} {ADJ_EN}. | D9: {SUBJ_PRONOUN_ES} {COP_ES} {ADJ_ES}. | E9: Pronoun with attribute | F9: 2pl | G9: 1-cop | H9: PRS | I9: Simple | K9: Active | L9: aff | M9: Statement | N9: None | O9: Y'all are big | P9: 0.002023415 | Q9: 1 | R9: 0.0014870409
A10: 9 | B10: {SUBJ_PRONOUN} {OCCUPATION}. | C10: {SUBJ_PRONOUN_EN} {BE_EN} {OCCUPATION_EN}. | D10: {SUBJ_PRONOUN_ES} {COP_ES} {OCCUPATION_ES}. | E10: Pronoun with occupation, more common variant | F10: 3sg | G10: 1-cop | H10: PRS | I10: Simple | K10: Active | L10: aff | M10: Statement | N10: Is occupation | O10: She is a fireman | P10: 0.0027925494 | Q10: 0.75 | R10: 0.0015392178
A11: 10 | B11: {ADJ}{AFFIX_PRONOUN} {SUBJ_PRONOUN}. | C11: {SUBJ_PRONOUN_EN} {BE_EN} {ADJ_EN}. | D11: {SUBJ_PRONOUN_ES} {COP_ES} {ADJ_ES}. | E11: Pronoun with attribute | F11: 3sg | G11: 1-cop | H11: PRS | I11: Simple | K11: Active | L11: aff | M11: Statement | N11: None | O11: He is kind. | P11: 0.0027925494 | Q11: 1 | R11: 0.0020522904
A12: 11 | B12: {OCCUPATION} {NAME}. | C12: {NAME_EN} {BE_EN} {OCCUPATION_EN}. | D12: {NAME_ES} {COP_ES} {OCCUPATION_ES}. | E12: Name with occupation | F12: 3sg - Name | G12: 1-cop | H12: PRS | I12: Simple | K12: Active | L12: aff | M12: Statement | N12: Is occupation | O12: Mateo is a chef | P12: 0.0027925494 | Q12: 1 | R12: 0.0020522904
A13: 12 | B13: {ADJ} {NAME}. | C13: {NAME_EN} {BE_EN} {ADJ_EN}. | D13: {NAME_ES} {COP_ES} {ADJ_ES}. | E13: Attribute predicate: a name described by an adjective. | F13: 3sg - Name | G13: 1-cop | H13: PRS | I13: Simple | K13: Active | L13: aff | M13: Statement | N13: None | O13: Carlos is kind | P13: 0.0027925494 | Q13: 1 | R13: 0.0020522904
... A22: 21 | B22: {ADJ} {POSS_NP}. | C22: {POSS_NP_EN} {BE_EN} {ADJ_EN}. | D22: {POSS_NP_ES} {COP_ES} {ADJ_ES}. | E22: Attributive predicate: a possessed noun described by an adjective. | F22: 3sg - Possesed noun | G22: 1-cop | H22: PRS | I22: Simple | K22: Active | L22: aff | M22: Statement | N22: None | O22: My wife is kind. | P22: 0.0027925494 | Q22: 1 | R22: 0.0020522904
A23: 22 | B23: {WH_LOC} {EXIST} {NAME}? | C23: {WH_LOC_EN} {BE_EN} {NAME_EN}? | D23: ¿{WH_LOC_ES} {COP_ES} {NAME_ES}? | F23: 3sg - Name | G23: 1-cop | H23: PRS | I23: Simple | K23: Active | L23: aff | M23: Where question | N23: None | O23: Where is Mateo? | P23: 0.00023271245 | Q23: 1 | R23: 0.0001710242
A24: 23 | B24: {WH_LOC} {EXIST} {NP}? | C24: {WH_LOC_EN} {BE_EN} {NP_EN}? | D24: ¿{WH_LOC_ES} {COP_ES} {NP_ES}? | E24: WH-locative question about an NP. | F24: 3sg - Noun | G24: 1-cop | H24: PRS | I24: Simple | K24: Active | L24: aff | M24: Where question | N24: None | O24: Where is the phone? | P24: 0.00023271245 | Q24: 1 | R24: 0.0001710242
A25: 24 | B25: {WH_LOC} {EXIST} {NP} {ADJ}? | C25: {WH_LOC_EN} {BE_EN} {ADJ_EN} {NP_EN}? | D25: ¿{WH_LOC_ES} {COP_ES} {ADJ_ES} {NP_ES}? | E25: WH-locative question about a noun with attribute | F25: 3sg - Noun | G25: 1-cop | H25: PRS | I25: Simple | K25: Active | L25: aff | M25: Where question | N25: None | O25: Where is the big phone? | P25: 0.00023271245 | Q25: 1 | R25: 0.0001710242
A26: 26 | B26: {WH_LOC} {EXIST} {POSS_NP_PL}? | C26: {WH_LOC_EN} {BE_EN} {POSS_NP_PL_EN}? | D26: ¿{WH_LOC_ES} {COP_ES} {POSS_NP_PL_ES}? | E26: WH-locative question about a possessed NP. | F26: 3pl - Possessed noun | G26: 1-cop | H26: PRS | I26: Simple | K26: Active | L26: aff | M26: Where question | N26: None | O26: Where are my brothers? | P26: 8.7267168e-05 | Q26: 1 | R26: 6.4134075e-05
A27: 28 | B27: {WH_LOC} {EXIST} {POSS_NP}? | C27: {WH_LOC_EN} {BE_EN} {POSS_NP_EN}? | D27: ¿{WH_LOC_ES} {COP_ES} {POSS_NP_ES}? | E27: WH-locative question about a possessed NP. | F27: 3sg - Possesed noun | G27: 1-cop | H27: PRS | I27: Simple | K27: Active | L27: aff | M27: Where question | N27: None | O27: Where is my phone? | P27: 0.00023271245 | Q27: 1 | R27: 0.0001710242
A28: 29 | B28: {YN_Q_MARKER} {OCCUPATION} {NAME}? | C28: {BE_EN} {NAME_EN} {OCCUPATION_EN}? | D28: ¿{NAME_ES} {COP_ES} {OCCUPATION_ES}? | F28: 3sg - Name | G28: 1-cop | H28: PRS | I28: Simple | K28: Active | L28: aff | M28: Yes/no question | N28: Is occupation | O28: Is Mateo a fireman? | P28: 0.00069813735 | Q28: 1 | R28: 0.0005130726
A29: 30 | B29: {YN_Q_MARKER} {ADJ} {NAME}? | C29: {BE_EN} {NAME_EN} {ADJ_EN}? | D29: ¿{NAME_ES} {COP_ES} {ADJ_ES}? | F29: 3sg - Name | G29: 1-cop | H29: PRS | I29: Simple | K29: Active | L29: aff | M29: Yes/no question | N29: None | O29: Is Carlos kind? | P29: 0.00069813735 | Q29: 1 | R29: 0.0005130726
A30: 31 | B30: {YN_Q_MARKER} {ADJ} {NP}? | C30: {BE_EN} {NP_EN} {ADJ_EN}? | D30: ¿{NP_ES} {COP_ES} {ADJ_ES}? | E30: Yes/no attributive question. | F30: 3sg - Noun | G30: 1-cop | H30: PRS | I30: Simple | K30: Active | L30: aff | M30: Yes/no question | N30: None | O30: Is the house big? | P30: 0.00069813735 | Q30: 1 | R30: 0.0005130726
A31: 32 | B31: {YN_Q_MARKER} {ADJ} {NP}? | C31: {BE_EN} {NP_EN} {ADJ_EN}? | D31: ¿{COP_ES} {ADJ_ES} {NP_ES}? | E31: Yes/no attributive question. Variant for Spanish. | F31: 3sg - Noun | G31: 1-cop | H31: PRS | I31: Simple | K31: Active | L31: aff | M31: Yes/no question | N31: None | O31: Is the house big? | P31: 0.00069813735 | Q31: 1 | R31: 0.0005130726
A32: 33 | B32: {YN_Q_MARKER} {ADJ} {NP_PL}? | C32: {BE_EN} {NP_PL_EN} {ADJ_EN}? | D32: ¿{COP_ES} {NP_PL_ES} {ADJ_ES}? | E32: Yes/no attributive question. | F32: 3pl - Noun def | G32: 1-cop | H32: PRS | I32: Simple | K32: Active | L32: aff | M32: Yes/no question | N32: None | O32: Are the houses big? | P32: 0.00026180151 | Q32: 1 | R32: 0.00019240222
A33: 34 | B33: {YN_Q_MARKER} {ADJ} {NP_PL}? | C33: {BE_EN} {NP_PL_INDEF_EN} {ADJ_EN}? | D33: ¿{COP_ES} {NP_PL_ES} {ADJ_ES}? | E33: Yes/no attributive question. | F33: 3pl - Noun indef | G33: 1-cop | H33: PRS | I33: Simple | K33: Active | L33: aff | M33: Yes/no question | N33: None | O33: Are mice small? | P33: 0.00026180151 | Q33: 1 | R33: 0.00019240222
A34: 35 | B34: {YN_Q_MARKER} {ADJ} {POSS_NP_PL_PRE}? | C34: {BE_EN} {POSS_NP_PL_EN} {ADJ_EN}? | D34: ¿{COP_ES} {ADJ_ES} {POSS_NP_PL_ES}? | E34: Yes/no question for an attributive predicate, possessed noun has preposed plural marker | F34: 3pl - Possessed noun | G34: 1-cop | H34: PRS | I34: Simple | K34: Active | L34: aff | M34: Yes/no question | N34: None | O34: Are my brothers kind? | P34: 0.00026180151 | Q34: 1 | R34: 0.00019240222
A35: 36 | B35: {YN_Q_MARKER} {ADJ} {POSS_NP_PL_POST}? | C35: {BE_EN} {POSS_NP_PL_EN} {ADJ_EN}? | D35: ¿{COP_ES} {ADJ_ES} {POSS_NP_PL_ES}? | E35: Yes/no question for an attributive predicate, possessed noun has postposed plural marker | F35: 3pl - Possessed noun | G35: 1-cop | H35: PRS | I35: Simple | K35: Active | L35: aff | M35: Yes/no question | N35: None | O35: Are my brothers kind? | P35: 0.00026180151 | Q35: 1 | R35: 0.00019240222
A36: 37 | B36: {YN_Q_MARKER} {ADJ} {POSS_NP}? | C36: {BE_EN} {POSS_NP_EN} {ADJ_EN}? | D36: ¿{POSS_NP_ES} {COP_ES} {ADJ_ES}? | E36: Yes/no question for an attributive predicate. | F36: 3sg - Possesed noun | G36: 1-cop | H36: PRS | I36: Simple | K36: Active | L36: aff | M36: Yes/no question | N36: None | O36: Is my wife kind? | P36: 0.00069813735 | Q36: 1 | R36: 0.0005130726
A37: 38 | B37: {YN_Q_MARKER} {ADJ} {POSS_NP}? | C37: {BE_EN} {POSS_NP_EN} {ADJ_EN}? | D37: ¿{COP_ES} {ADJ_ES} {POSS_NP_ES}? | E37: Yes/no question for an attributive predicate. Variant for Spanish. | F37: 3sg - Possesed noun | G37: 1-cop | H37: PRS | I37: Simple | K37: Active | L37: aff | M37: Yes/no question | N37: None | O37: Is my wife kind? | P37: 0.00069813735 | Q37: 1 | R37: 0.0005130726
A38: 39 | B38: {NEG_PRE} {ADJ} {NEG_SUF} {NAME}. | C38: {NAME_EN} {BE_NEG_EN} {ADJ_EN}. | D38: {NAME_ES} {COP_NEG_ES} {ADJ_ES}. | F38: 3sg - Name | G38: 1-cop | H38: PRS | I38: Simple | K38: Active | L38: neg | M38: Statement | N38: None | O38: Carlos is not kind | P38: 0.00049280283 | Q38: 1 | R38: 0.00036216889
A39: 40 | B39: {NEG_PRE} {ADJ} {NEG_SUF} {NP}. | C39: {NP_EN} {BE_NEG_EN} {ADJ_EN}. | D39: {NP_ES} {COP_NEG_ES} {ADJ_ES}. | E39: Negative attributive predicate. | F39: 3sg - Noun | G39: 1-cop | H39: PRS | I39: Simple | K39: Active | L39: neg | M39: Statement | N39: None | O39: The house is not big. | P39: 0.00049280283 | Q39: 1 | R39: 0.00036216889
A40: 41 | B40: {NEG_PRE} {ADJ} {NEG_SUF} {NP_PL}. | C40: {NP_PL_EN} {BE_NEG_EN} {ADJ_EN}. | D40: {NP_PL_ES} {COP_NEG_ES} {ADJ_ES}. | E40: Negative attributive predicate. | F40: 3pl - Noun def | G40: 1-cop | H40: PRS | I40: Simple | K40: Active | L40: neg | M40: Statement | N40: None | O40: The houses are not big. | P40: 0.00018480106 | Q40: 1 | R40: 0.00013581333
A41: 42 | B41: {NEG_PRE} {ADJ} {NEG_SUF} {NP_PL}. | C41: {NP_PL_INDEF_EN} {BE_NEG_EN} {ADJ_EN}. | D41: {NP_PL_ES} {COP_NEG_ES} {ADJ_ES}. | E41: Negative attributive predicate. | F41: 3pl - Noun indef | G41: 1-cop | H41: PRS | I41: Simple | K41: Active | L41: neg | M41: Statement | N41: None | O41: Mice are not big. | P41: 0.00018480106 | Q41: 1 | R41: 0.00013581333
A42: 43 | B42: {NEG_PRE} {ADJ} {NEG_SUF} {POSS_NP_PL_PRE}. | C42: {POSS_NP_PL_EN} {BE_NEG_EN} {ADJ_EN}. | D42: {POSS_NP_PL_ES} {COP_NEG_ES} {ADJ_ES}. | E42: Negative attributive predicate for possessed subject (preposed plural marker) | F42: 3pl - Possessed noun | G42: 1-cop | H42: PRS | I42: Simple | K42: Active | L42: neg | M42: Statement | N42: None | O42: My brothers are not kind. | P42: 0.00018480106 | Q42: 1 | R42: 0.00013581333
A43: 44 | B43: {NEG_PRE} {ADJ} {NEG_SUF} {POSS_NP_PL_POST}. | C43: {POSS_NP_PL_EN} {BE_NEG_EN} {ADJ_EN}. | D43: {POSS_NP_PL_ES} {COP_NEG_ES} {ADJ_ES}. | E43: Negative attributive predicate for possessed subject (postposed plural marker) | F43: 3pl - Possessed noun | G43: 1-cop | H43: PRS | I43: Simple | K43: Active | L43: neg | M43: Statement | N43: None | O43: My brothers are not kind. | P43: 0.00018480106 | Q43: 1 | R43: 0.00013581333
A44: 45 | B44: {NEG_PRE} {ADJ} {NEG_SUF} {POSS_NP}. | C44: {POSS_NP_EN} {BE_NEG_EN} {ADJ_EN}. | D44: {POSS_NP_ES} {COP_NEG_ES} {ADJ_ES}. | E44: Negative attributive predicate for possessed subject. | F44: 3sg - Possesed noun | G44: 1-cop | H44: PRS | I44: Simple | K44: Active | L44: neg | M44: Statement | N44: None | O44: My wife is not kind. | P44: 0.00049280283 | Q44: 1 | R44: 0.00036216889
A45: 49 | B45: {V_INTR_IMP_NEG}! | C45: Don't {V_INTR_BASE_EN}! | D45: {V_INTR_IMP_NEG_ES}! | F45: 2sg | G45: 2-intr | H45: PRS | I45: Simple | J45: IMP | K45: Active | L45: neg | M45: Command | N45: None | O45: Don't dance! | P45: 3.4286868e-05 | Q45: 1 | R45: 2.5197982e-05
A46: 50 | B46: {V_INTR_IMP_NEG_PL}! | C46: Don't {V_INTR_BASE_EN}! | D46: {V_INTR_IMP_USTEDES_NEG_ES}! | F46: 2pl | G46: 2-intr | H46: PRS | I46: Simple | J46: IMP | K46: Active | L46: neg | M46: Command | N46: None | O46: Don't sleep! | P46: 1.9286363e-05 | Q46: 1 | R46: 1.4173865e-05
A47: 51 | B47: {V_INTR_PROG}. | C47: {SUBJ_PRONOUN_EN} {BE_EN} {V_INTR_PROG_EN}. | D47: {SUBJ_PRONOUN_ES} {V_INTR_PROG_ES}. | E47: Intransitive progressive (present) with pronoun subject. | F47: 1sg | G47: 2-intr | H47: PRS | I47: PROG | K47: Active | L47: aff | M47: Statement | N47: None | O47: I am running. | P47: 0.0034709653 | Q47: 1 | R47: 0.0025508694
A48: 52 | B48: {V_INTR_PROG}. | C48: {SUBJ_PRONOUN_EN} {BE_EN} {V_INTR_PROG_EN}. | D48: {SUBJ_PRONOUN_ES} {V_INTR_PROG_ES}. | E48: Intransitive progressive (present) with pronoun subject. | F48: 1pl | G48: 2-intr | H48: PRS | I48: PROG | K48: Active | L48: aff | M48: Statement | N48: None | P48: 0.001952418 | Q48: 1 | R48: 0.001434864
...

Sheet full_list
A1: id | B1: kek | C1: en | D1: es | E1: description | F1: Subject | G1: Transitivity | H1: Tense | I1: Aspect | J1: Mood | K1: Voice | L1: Polarity | M1: Q/S/C | N1: Modifier | O1: example_en | P1: p_value | Q1: variant_dist | R1: p_value_norm | S1: Notes
A2: 1 | B2: {OCCUPATION}{AFFIX_PRONOUN}. | C2: {SUBJ_PRONOUN_EN} {BE_EN} {OCCUPATION_EN}. | D2: {SUBJ_PRONOUN_ES} {COP_ES} {OCCUPATION_ES}. | E2: Pronoun with occupation | F2: 1sg | G2: 1-cop | H2: PRS | I2: Simple | K2: Active | L2: aff | M2: Statement | N2: Is occupation | O2: I am a fireman | P2: =PRODUCT(_xlfn.XLOOKUP(F2,Config!$A$2:$A$15,Config!$B$2:$B$15),_xlfn.XLOOKUP(G2,Config!$C$2:$C$7,Config!$D$2:$D$7),_xlfn.XLOOKUP(H2,Config!$E$2:$E$5,Config!$F$2:$F$5),_xlfn.XLOOKUP(I2,Config!$G$2:$G$3,Config!$H$2:$H$3),_xlfn.XLOOKUP(J2,Config!$I$2:$I$3,Config!$J$2:$J$3),_xlfn.XLOOKUP(K2,Config!$K$2:$K$3,Config!$L$2:$L$3),_xlfn.XLOOKUP(L2,Config!$M$2:$M$3,Config!$N$2:$N$3),_xlfn.XLOOKUP(M2,Config!$O$2:$O$6,Config!$P$2:$P$6)) -> 0.0041651584 | Q2: =0.25*0.5 -> 0.125 | R2: =P2*Q2*Config!$B$19 -> 0.00038263041
A3: 2 | B3: {ADJ}{AFFIX_PRONOUN}. | C3: {SUBJ_PRONOUN_EN} {BE_EN} {ADJ_EN}. | D3: {SUBJ_PRONOUN_ES} {COP_ES} {ADJ_ES}. | E3: Pronoun with attribute | F3: 1sg | G3: 1-cop | H3: PRS | I3: Simple | K3: Active | L3: aff | M3: Statement | N3: None | O3: I am big | P3: =PRODUCT(_xlfn.XLOOKUP(F3,Config!$A$2:$A$15,Config!$B$2:$B$15),_xlfn.XLOOKUP(G3,Config!$C$2:$C$7,Config!$D$2:$D$7),_xlfn.XLOOKUP(H3,Config!$E$2:$E$5,Config!$F$2:$F$5),_xlfn.XLOOKUP(I3,Config!$G$2:$G$3,Config!$H$2:$H$3),_xlfn.XLOOKUP(J3,Config!$I$2:$I$3,Config!$J$2:$J$3),_xlfn.XLOOKUP(K3,Config!$K$2:$K$3,Config!$L$2:$L$3),_xlfn.XLOOKUP(L3,Config!$M$2:$M$3,Config!$N$2:$N$3),_xlfn.XLOOKUP(M3,Config!$O$2:$O$6,Config!$P$2:$P$6)) -> 0.0041651584 | Q3: 0.5 | R3: =P3*Q3*Config!$B$19 -> 0.0015305216
A4: 3 | B4: {PRED_NP}{AFFIX_PRONOUN}. | C4: {SUBJ_PRONOUN_EN} {BE_EN} {PRED_NP_EN}. | D4: {SUBJ_PRONOUN_ES} {V_SER_ES} {PRED_NP_ES}. | E4: Noun in stative sentence | F4: 1sg | G4: 1-cop | H4: PRS | I4: Simple | K4: Active | L4: aff | M4: Statement | N4: None | O4: I am a boy | P4: =PRODUCT(_xlfn.XLOOKUP(F4,Config!$A$2:$A$15,Config!$B$2:$B$15),_xlfn.XLOOKUP(G4,Config!$C$2:$C$7,Config!$D$2:$D$7),_xlfn.XLOOKUP(H4,Config!$E$2:$E$5,Config!$F$2:$F$5),_xlfn.XLOOKUP(I4,Config!$G$2:$G$3,Config!$H$2:$H$3),_xlfn.XLOOKUP(J4,Config!$I$2:$I$3,Config!$J$2:$J$3),_xlfn.XLOOKUP(K4,Config!$K$2:$K$3,Config!$L$2:$L$3),_xlfn.XLOOKUP(L4,Config!$M$2:$M$3,Config!$N$2:$N$3),_xlfn.XLOOKUP(M4,Config!$O$2:$O$6,Config!$P$2:$P$6)) -> 0.0041651584 | Q4: 0.5 | R4: =P4*Q4*Config!$B$19 -> 0.0015305216
A5: 4 | B5: {ADJ}{AFFIX_PRONOUN}. | C5: {SUBJ_PRONOUN_EN} {BE_EN} {ADJ_EN}. | D5: {SUBJ_PRONOUN_ES} {COP_ES} {ADJ_ES}. | E5: Pronoun with attribute | F5: 1pl | G5: 1-cop | H5: PRS | I5: Simple | K5: Active | L5: aff | M5: Statement | N5: None | O5: We are big | P5: =PRODUCT(_xlfn.XLOOKUP(F5,Config!$A$2:$A$15,Config!$B$2:$B$15),_xlfn.XLOOKUP(G5,Config!$C$2:$C$7,Config!$D$2:$D$7),_xlfn.XLOOKUP(H5,Config!$E$2:$E$5,Config!$F$2:$F$5),_xlfn.XLOOKUP(I5,Config!$G$2:$G$3,Config!$H$2:$H$3),_xlfn.XLOOKUP(J5,Config!$I$2:$I$3,Config!$J$2:$J$3),_xlfn.XLOOKUP(K5,Config!$K$2:$K$3,Config!$L$2:$L$3),_xlfn.XLOOKUP(L5,Config!$M$2:$M$3,Config!$N$2:$N$3),_xlfn.XLOOKUP(M5,Config!$O$2:$O$6,Config!$P$2:$P$6)) -> 0.0023429016 | Q5: 1 | R5: =P5*Q5*Config!$B$19 -> 0.0017218369
A6: 5 | B6: {OCCUPATION}{AFFIX_PRONOUN}. | C6: {SUBJ_PRONOUN_EN} {BE_EN} {OCCUPATION_EN}. | D6: {SUBJ_PRONOUN_ES} {COP_ES} {OCCUPATION_ES}. | E6: Pronoun with occupation | F6: 2sg | G6: 1-cop | H6: PRS | I6: Simple | K6: Active | L6: aff | M6: Statement | N6: Is occupation | O6: You are a chef | P6: =PRODUCT(_xlfn.XLOOKUP(F6,Config!$A$2:$A$15,Config!$B$2:$B$15),_xlfn.XLOOKUP(G6,Config!$C$2:$C$7,Config!$D$2:$D$7),_xlfn.XLOOKUP(H6,Config!$E$2:$E$5,Config!$F$2:$F$5),_xlfn.XLOOKUP(I6,Config!$G$2:$G$3,Config!$H$2:$H$3),_xlfn.XLOOKUP(J6,Config!$I$2:$I$3,Config!$J$2:$J$3),_xlfn.XLOOKUP(K6,Config!$K$2:$K$3,Config!$L$2:$L$3),_xlfn.XLOOKUP(L6,Config!$M$2:$M$3,Config!$N$2:$N$3),_xlfn.XLOOKUP(M6,Config!$O$2:$O$6,Config!$P$2:$P$6)) -> 0.0035971823 | Q6: 0.25 | R6: =P6*Q6*Config!$B$19 -> 0.00066090707
A7: 6 | B7: {ADJ}{AFFIX_PRONOUN}. | C7: {SUBJ_PRONOUN_EN} {BE_EN} {ADJ_EN}. | D7: {SUBJ_PRONOUN_ES} {COP_ES} {ADJ_ES}. | E7: Pronoun with attribute | F7: 2sg | G7: 1-cop | H7: PRS | I7: Simple | K7: Active | L7: aff | M7: Statement | N7: None | O7: You are big | P7: =PRODUCT(_xlfn.XLOOKUP(F7,Config!$A$2:$A$15,Config!$B$2:$B$15),_xlfn.XLOOKUP(G7,Config!$C$2:$C$7,Config!$D$2:$D$7),_xlfn.XLOOKUP(H7,Config!$E$2:$E$5,Config!$F$2:$F$5),_xlfn.XLOOKUP(I7,Config!$G$2:$G$3,Config!$H$2:$H$3),_xlfn.XLOOKUP(J7,Config!$I$2:$I$3,Config!$J$2:$J$3),_xlfn.XLOOKUP(K7,Config!$K$2:$K$3,Config!$L$2:$L$3),_xlfn.XLOOKUP(L7,Config!$M$2:$M$3,Config!$N$2:$N$3),_xlfn.XLOOKUP(M7,Config!$O$2:$O$6,Config!$P$2:$P$6)) -> 0.0035971823 | Q7: 1 | R7: =P7*Q7*Config!$B$19 -> 0.0026436283
A8: 7 | B8: {OCCUPATION}{AFFIX_PRONOUN} {SUBJ_PRONOUN}. | C8: {SUBJ_PRONOUN_EN} {BE_EN} {OCCUPATION_EN}. | D8: {SUBJ_PRONOUN_ES} {COP_ES} {OCCUPATION_ES}. | E8: Pronoun with occupation | F8: 3sg | G8: 1-cop | H8: PRS | I8: Simple | K8: Active | L8: aff | M8: Statement | N8: Is occupation | O8: She is a fireman | P8: =PRODUCT(_xlfn.XLOOKUP(F8,Config!$A$2:$A$15,Config!$B$2:$B$15),_xlfn.XLOOKUP(G8,Config!$C$2:$C$7,Config!$D$2:$D$7),_xlfn.XLOOKUP(H8,Config!$E$2:$E$5,Config!$F$2:$F$5),_xlfn.XLOOKUP(I8,Config!$G$2:$G$3,Config!$H$2:$H$3),_xlfn.XLOOKUP(J8,Config!$I$2:$I$3,Config!$J$2:$J$3),_xlfn.XLOOKUP(K8,Config!$K$2:$K$3,Config!$L$2:$L$3),_xlfn.XLOOKUP(L8,Config!$M$2:$M$3,Config!$N$2:$N$3),_xlfn.XLOOKUP(M8,Config!$O$2:$O$6,Config!$P$2:$P$6)) -> 0.0027925494 | Q8: 0.25 | R8: =P8*Q8*Config!$B$19 -> 0.0005130726
A9: 8 | B9: {ADJ}{AFFIX_PRONOUN}. | C9: {SUBJ_PRONOUN_EN} {BE_EN} {ADJ_EN}. | D9: {SUBJ_PRONOUN_ES} {COP_ES} {ADJ_ES}. | E9: Pronoun with attribute | F9: 2pl | G9: 1-cop | H9: PRS | I9: Simple | K9: Active | L9: aff | M9: Statement | N9: None | O9: Y'all are big | P9: =PRODUCT(_xlfn.XLOOKUP(F9,Config!$A$2:$A$15,Config!$B$2:$B$15),_xlfn.XLOOKUP(G9,Config!$C$2:$C$7,Config!$D$2:$D$7),_xlfn.XLOOKUP(H9,Config!$E$2:$E$5,Config!$F$2:$F$5),_xlfn.XLOOKUP(I9,Config!$G$2:$G$3,Config!$H$2:$H$3),_xlfn.XLOOKUP(J9,Config!$I$2:$I$3,Config!$J$2:$J$3),_xlfn.XLOOKUP(K9,Config!$K$2:$K$3,Config!$L$2:$L$3),_xlfn.XLOOKUP(L9,Config!$M$2:$M$3,Config!$N$2:$N$3),_xlfn.XLOOKUP(M9,Config!$O$2:$O$6,Config!$P$2:$P$6)) -> 0.002023415 | Q9: 1 | R9: =P9*Q9*Config!$B$19 -> 0.0014870409
A10: 9 | B10: {SUBJ_PRONOUN} {OCCUPATION}. | C10: {SUBJ_PRONOUN_EN} {BE_EN} {OCCUPATION_EN}. | D10: {SUBJ_PRONOUN_ES} {COP_ES} {OCCUPATION_ES}. | E10: Pronoun with occupation, more common variant | F10: 3sg | G10: 1-cop | H10: PRS | I10: Simple | K10: Active | L10: aff | M10: Statement | N10: Is occupation | O10: She is a fireman | P10: =PRODUCT(_xlfn.XLOOKUP(F10,Config!$A$2:$A$15,Config!$B$2:$B$15),_xlfn.XLOOKUP(G10,Config!$C$2:$C$7,Config!$D$2:$D$7),_xlfn.XLOOKUP(H10,Config!$E$2:$E$5,Config!$F$2:$F$5),_xlfn.XLOOKUP(I10,Config!$G$2:$G$3,Config!$H$2:$H$3),_xlfn.XLOOKUP(J10,Config!$I$2:$I$3,Config!$J$2:$J$3),_xlfn.XLOOKUP(K10,Config!$K$2:$K$3,Config!$L$2:$L$3),_xlfn.XLOOKUP(L10,Config!$M$2:$M$3,Config!$N$2:$N$3),_xlfn.XLOOKUP(M10,Config!$O$2:$O$6,Config!$P$2:$P$6)) -> 0.0027925494 | Q10: 0.75 | R10: =P10*Q10*Config!$B$19 -> 0.0015392178
A11: 10 | B11: {ADJ}{AFFIX_PRONOUN} {SUBJ_PRONOUN}. | C11: {SUBJ_PRONOUN_EN} {BE_EN} {ADJ_EN}. | D11: {SUBJ_PRONOUN_ES} {COP_ES} {ADJ_ES}. | E11: Pronoun with attribute | F11: 3sg | G11: 1-cop | H11: PRS | I11: Simple | K11: Active | L11: aff | M11: Statement | N11: None | O11: He is kind. | P11: =PRODUCT(_xlfn.XLOOKUP(F11,Config!$A$2:$A$15,Config!$B$2:$B$15),_xlfn.XLOOKUP(G11,Config!$C$2:$C$7,Config!$D$2:$D$7),_xlfn.XLOOKUP(H11,Config!$E$2:$E$5,Config!$F$2:$F$5),_xlfn.XLOOKUP(I11,Config!$G$2:$G$3,Config!$H$2:$H$3),_xlfn.XLOOKUP(J11,Config!$I$2:$I$3,Config!$J$2:$J$3),_xlfn.XLOOKUP(K11,Config!$K$2:$K$3,Config!$L$2:$L$3),_xlfn.XLOOKUP(L11,Config!$M$2:$M$3,Config!$N$2:$N$3),_xlfn.XLOOKUP(M11,Config!$O$2:$O$6,Config!$P$2:$P$6)) -> 0.0027925494 | Q11: 1 | R11: =P11*Q11*Config!$B$19 -> 0.0020522904
A12: 11 | B12: {OCCUPATION} {NAME}. | C12: {NAME_EN} {BE_EN} {OCCUPATION_EN}. | D12: {NAME_ES} {COP_ES} {OCCUPATION_ES}. | E12: Name with occupation | F12: 3sg - Name | G12: 1-cop | H12: PRS | I12: Simple | K12: Active | L12: aff | M12: Statement | N12: Is occupation | O12: Mateo is a chef | P12: =PRODUCT(_xlfn.XLOOKUP(F12,Config!$A$2:$A$15,Config!$B$2:$B$15),_xlfn.XLOOKUP(G12,Config!$C$2:$C$7,Config!$D$2:$D$7),_xlfn.XLOOKUP(H12,Config!$E$2:$E$5,Config!$F$2:$F$5),_xlfn.XLOOKUP(I12,Config!$G$2:$G$3,Config!$H$2:$H$3),_xlfn.XLOOKUP(J12,Config!$I$2:$I$3,Config!$J$2:$J$3),_xlfn.XLOOKUP(K12,Config!$K$2:$K$3,Config!$L$2:$L$3),_xlfn.XLOOKUP(L12,Config!$M$2:$M$3,Config!$N$2:$N$3),_xlfn.XLOOKUP(M12,Config!$O$2:$O$6,Config!$P$2:$P$6)) -> 0.0027925494 | Q12: 1 | R12: =P12*Q12*Config!$B$19 -> 0.0020522904
A13: 12 | B13: {ADJ} {NAME}. | C13: {NAME_EN} {BE_EN} {ADJ_EN}. | D13: {NAME_ES} {COP_ES} {ADJ_ES}. | E13: Attribute predicate: a name described by an adjective. | F13: 3sg - Name | G13: 1-cop | H13: PRS | I13: Simple | K13: Active | L13: aff | M13: Statement | N13: None | O13: Carlos is kind | P13: =PRODUCT(_xlfn.XLOOKUP(F13,Config!$A$2:$A$15,Config!$B$2:$B$15),_xlfn.XLOOKUP(G13,Config!$C$2:$C$7,Config!$D$2:$D$7),_xlfn.XLOOKUP(H13,Config!$E$2:$E$5,Config!$F$2:$F$5),_xlfn.XLOOKUP(I13,Config!$G$2:$G$3,Config!$H$2:$H$3),_xlfn.XLOOKUP(J13,Config!$I$2:$I$3,Config!$J$2:$J$3),_xlfn.XLOOKUP(K13,Config!$K$2:$K$3,Config!$L$2:$L$3),_xlfn.XLOOKUP(L13,Config!$M$2:$M$3,Config!$N$2:$N$3),_xlfn.XLOOKUP(M13,Config!$O$2:$O$6,Config!$P$2:$P$6)) -> 0.0027925494 | Q13: 1 | R13: =P13*Q13*Config!$B$19 -> 0.0020522904
A14: 13 | B14: {ADJ} {NP}. | C14: {NP_EN} {BE_EN} {ADJ_EN}. | D14: {NP_ES} {COP_ES} {ADJ_ES}. | E14: Attributive predicate: a non-possessed noun described by an adjective. | F14: 3sg - Noun | G14: 1-cop | H14: PRS | I14: Simple | K14: Active | L14: aff | M14: Statement | N14: None | O14: The house is big. | P14: =PRODUCT(_xlfn.XLOOKUP(F14,Config!$A$2:$A$15,Config!$B$2:$B$15),_xlfn.XLOOKUP(G14,Config!$C$2:$C$7,Config!$D$2:$D$7),_xlfn.XLOOKUP(H14,Config!$E$2:$E$5,Config!$F$2:$F$5),_xlfn.XLOOKUP(I14,Config!$G$2:$G$3,Config!$H$2:$H$3),_xlfn.XLOOKUP(J14,Config!$I$2:$I$3,Config!$J$2:$J$3),_xlfn.XLOOKUP(K14,Config!$K$2:$K$3,Config!$L$2:$L$3),_xlfn.XLOOKUP(L14,Config!$M$2:$M$3,Config!$N$2:$N$3),_xlfn.XLOOKUP(M14,Config!$O$2:$O$6,Config!$P$2:$P$6)) -> 0.0027925494 | Q14: 1 | R14: =P14*Q14*Config!$B$19 -> 0.0020522904
... A22: 21 | B22: {ADJ} {POSS_NP}. | C22: {POSS_NP_EN} {BE_EN} {ADJ_EN}. | D22: {POSS_NP_ES} {COP_ES} {ADJ_ES}. | E22: Attributive predicate: a possessed noun described by an adjective. | F22: 3sg - Possesed noun | G22: 1-cop | H22: PRS | I22: Simple | K22: Active | L22: aff | M22: Statement | N22: None | O22: My wife is kind. | P22: =PRODUCT(_xlfn.XLOOKUP(F22,Config!$A$2:$A$15,Config!$B$2:$B$15),_xlfn.XLOOKUP(G22,Config!$C$2:$C$7,Config!$D$2:$D$7),_xlfn.XLOOKUP(H22,Config!$E$2:$E$5,Config!$F$2:$F$5),_xlfn.XLOOKUP(I22,Config!$G$2:$G$3,Config!$H$2:$H$3),_xlfn.XLOOKUP(J22,Config!$I$2:$I$3,Config!$J$2:$J$3),_xlfn.XLOOKUP(K22,Config!$K$2:$K$3,Config!$L$2:$L$3),_xlfn.XLOOKUP(L22,Config!$M$2:$M$3,Config!$N$2:$N$3),_xlfn.XLOOKUP(M22,Config!$O$2:$O$6,Config!$P$2:$P$6)) -> 0.0027925494 | Q22: 1 | R22: =P22*Q22*Config!$B$19 -> 0.0020522904
A23: 22 | B23: {WH_LOC} {EXIST} {NAME}? | C23: {WH_LOC_EN} {BE_EN} {NAME_EN}? | D23: ¿{WH_LOC_ES} {COP_ES} {NAME_ES}? | F23: 3sg - Name | G23: 1-cop | H23: PRS | I23: Simple | K23: Active | L23: aff | M23: Where question | N23: None | O23: Where is Mateo? | P23: =PRODUCT(_xlfn.XLOOKUP(F23,Config!$A$2:$A$15,Config!$B$2:$B$15),_xlfn.XLOOKUP(G23,Config!$C$2:$C$7,Config!$D$2:$D$7),_xlfn.XLOOKUP(H23,Config!$E$2:$E$5,Config!$F$2:$F$5),_xlfn.XLOOKUP(I23,Config!$G$2:$G$3,Config!$H$2:$H$3),_xlfn.XLOOKUP(J23,Config!$I$2:$I$3,Config!$J$2:$J$3),_xlfn.XLOOKUP(K23,Config!$K$2:$K$3,Config!$L$2:$L$3),_xlfn.XLOOKUP(L23,Config!$M$2:$M$3,Config!$N$2:$N$3),_xlfn.XLOOKUP(M23,Config!$O$2:$O$6,Config!$P$2:$P$6)) -> 0.00023271245 | Q23: 1 | R23: =P23*Q23*Config!$B$19 -> 0.0001710242
A24: 23 | B24: {WH_LOC} {EXIST} {NP}? | C24: {WH_LOC_EN} {BE_EN} {NP_EN}? | D24: ¿{WH_LOC_ES} {COP_ES} {NP_ES}? | E24: WH-locative question about an NP. | F24: 3sg - Noun | G24: 1-cop | H24: PRS | I24: Simple | K24: Active | L24: aff | M24: Where question | N24: None | O24: Where is the phone? | P24: =PRODUCT(_xlfn.XLOOKUP(F24,Config!$A$2:$A$15,Config!$B$2:$B$15),_xlfn.XLOOKUP(G24,Config!$C$2:$C$7,Config!$D$2:$D$7),_xlfn.XLOOKUP(H24,Config!$E$2:$E$5,Config!$F$2:$F$5),_xlfn.XLOOKUP(I24,Config!$G$2:$G$3,Config!$H$2:$H$3),_xlfn.XLOOKUP(J24,Config!$I$2:$I$3,Config!$J$2:$J$3),_xlfn.XLOOKUP(K24,Config!$K$2:$K$3,Config!$L$2:$L$3),_xlfn.XLOOKUP(L24,Config!$M$2:$M$3,Config!$N$2:$N$3),_xlfn.XLOOKUP(M24,Config!$O$2:$O$6,Config!$P$2:$P$6)) -> 0.00023271245 | Q24: 1 | R24: =P24*Q24*Config!$B$19 -> 0.0001710242
A25: 24 | B25: {WH_LOC} {EXIST} {NP} {ADJ}? | C25: {WH_LOC_EN} {BE_EN} {ADJ_EN} {NP_EN}? | D25: ¿{WH_LOC_ES} {COP_ES} {ADJ_ES} {NP_ES}? | E25: WH-locative question about a noun with attribute | F25: 3sg - Noun | G25: 1-cop | H25: PRS | I25: Simple | K25: Active | L25: aff | M25: Where question | N25: None | O25: Where is the big phone? | P25: =PRODUCT(_xlfn.XLOOKUP(F25,Config!$A$2:$A$15,Config!$B$2:$B$15),_xlfn.XLOOKUP(G25,Config!$C$2:$C$7,Config!$D$2:$D$7),_xlfn.XLOOKUP(H25,Config!$E$2:$E$5,Config!$F$2:$F$5),_xlfn.XLOOKUP(I25,Config!$G$2:$G$3,Config!$H$2:$H$3),_xlfn.XLOOKUP(J25,Config!$I$2:$I$3,Config!$J$2:$J$3),_xlfn.XLOOKUP(K25,Config!$K$2:$K$3,Config!$L$2:$L$3),_xlfn.XLOOKUP(L25,Config!$M$2:$M$3,Config!$N$2:$N$3),_xlfn.XLOOKUP(M25,Config!$O$2:$O$6,Config!$P$2:$P$6)) -> 0.00023271245 | Q25: 1 | R25: =P25*Q25*Config!$B$19 -> 0.0001710242
A26: 25 | B26: {WH_LOC} {EXIST} {NP_PL}? | C26: {WH_LOC_EN} {BE_EN} {NP_PL_EN}? | D26: ¿{WH_LOC_ES} {COP_ES} {NP_PL_ES}? | E26: WH-locative question about an NP. | F26: 3pl - Noun def | G26: 1-cop | H26: PRS | I26: Simple | K26: Active | L26: aff | M26: Where question | N26: None | O26: Where are the pigs? | P26: =PRODUCT(_xlfn.XLOOKUP(F26,Config!$A$2:$A$15,Config!$B$2:$B$15),_xlfn.XLOOKUP(G26,Config!$C$2:$C$7,Config!$D$2:$D$7),_xlfn.XLOOKUP(H26,Config!$E$2:$E$5,Config!$F$2:$F$5),_xlfn.XLOOKUP(I26,Config!$G$2:$G$3,Config!$H$2:$H$3),_xlfn.XLOOKUP(J26,Config!$I$2:$I$3,Config!$J$2:$J$3),_xlfn.XLOOKUP(K26,Config!$K$2:$K$3,Config!$L$2:$L$3),_xlfn.XLOOKUP(L26,Config!$M$2:$M$3,Config!$N$2:$N$3),_xlfn.XLOOKUP(M26,Config!$O$2:$O$6,Config!$P$2:$P$6)) -> 8.7267168e-05 | Q26: 1 | R26: =P26*Q26*Config!$B$19 -> 6.4134075e-05
A27: 26 | B27: {WH_LOC} {EXIST} {POSS_NP_PL}? | C27: {WH_LOC_EN} {BE_EN} {POSS_NP_PL_EN}? | D27: ¿{WH_LOC_ES} {COP_ES} {POSS_NP_PL_ES}? | E27: WH-locative question about a possessed NP. | F27: 3pl - Possessed noun | G27: 1-cop | H27: PRS | I27: Simple | K27: Active | L27: aff | M27: Where question | N27: None | O27: Where are my brothers? | P27: =PRODUCT(_xlfn.XLOOKUP(F27,Config!$A$2:$A$15,Config!$B$2:$B$15),_xlfn.XLOOKUP(G27,Config!$C$2:$C$7,Config!$D$2:$D$7),_xlfn.XLOOKUP(H27,Config!$E$2:$E$5,Config!$F$2:$F$5),_xlfn.XLOOKUP(I27,Config!$G$2:$G$3,Config!$H$2:$H$3),_xlfn.XLOOKUP(J27,Config!$I$2:$I$3,Config!$J$2:$J$3),_xlfn.XLOOKUP(K27,Config!$K$2:$K$3,Config!$L$2:$L$3),_xlfn.XLOOKUP(L27,Config!$M$2:$M$3,Config!$N$2:$N$3),_xlfn.XLOOKUP(M27,Config!$O$2:$O$6,Config!$P$2:$P$6)) -> 8.7267168e-05 | Q27: 1 | R27: =P27*Q27*Config!$B$19 -> 6.4134075e-05
A28: 27 | B28: {WH_LOC} {EXIST} {NP_PL} {ADJ}? | C28: {WH_LOC_EN} {BE_EN} {ADJ_EN} {NP_PL_EN}? | D28: ¿{WH_LOC_ES} {COP_ES} {NP_PL_ES} {ADJ_ES}? | E28: WH-locative question about an noun in plural with attribute. | F28: 3pl - Noun def with attribute | G28: 1-cop | H28: PRS | I28: Simple | K28: Active | L28: aff | M28: Where question | N28: None | O28: Where are the big pigs? | P28: =PRODUCT(_xlfn.XLOOKUP(F28,Config!$A$2:$A$15,Config!$B$2:$B$15),_xlfn.XLOOKUP(G28,Config!$C$2:$C$7,Config!$D$2:$D$7),_xlfn.XLOOKUP(H28,Config!$E$2:$E$5,Config!$F$2:$F$5),_xlfn.XLOOKUP(I28,Config!$G$2:$G$3,Config!$H$2:$H$3),_xlfn.XLOOKUP(J28,Config!$I$2:$I$3,Config!$J$2:$J$3),_xlfn.XLOOKUP(K28,Config!$K$2:$K$3,Config!$L$2:$L$3),_xlfn.XLOOKUP(L28,Config!$M$2:$M$3,Config!$N$2:$N$3),_xlfn.XLOOKUP(M28,Config!$O$2:$O$6,Config!$P$2:$P$6)) -> 8.7267168e-05 | Q28: 1 | R28: =P28*Q28*Config!$B$19 -> 6.4134075e-05
A29: 28 | B29: {WH_LOC} {EXIST} {POSS_NP}? | C29: {WH_LOC_EN} {BE_EN} {POSS_NP_EN}? | D29: ¿{WH_LOC_ES} {COP_ES} {POSS_NP_ES}? | E29: WH-locative question about a possessed NP. | F29: 3sg - Possesed noun | G29: 1-cop | H29: PRS | I29: Simple | K29: Active | L29: aff | M29: Where question | N29: None | O29: Where is my phone? | P29: =PRODUCT(_xlfn.XLOOKUP(F29,Config!$A$2:$A$15,Config!$B$2:$B$15),_xlfn.XLOOKUP(G29,Config!$C$2:$C$7,Config!$D$2:$D$7),_xlfn.XLOOKUP(H29,Config!$E$2:$E$5,Config!$F$2:$F$5),_xlfn.XLOOKUP(I29,Config!$G$2:$G$3,Config!$H$2:$H$3),_xlfn.XLOOKUP(J29,Config!$I$2:$I$3,Config!$J$2:$J$3),_xlfn.XLOOKUP(K29,Config!$K$2:$K$3,Config!$L$2:$L$3),_xlfn.XLOOKUP(L29,Config!$M$2:$M$3,Config!$N$2:$N$3),_xlfn.XLOOKUP(M29,Config!$O$2:$O$6,Config!$P$2:$P$6)) -> 0.00023271245 | Q29: 1 | R29: =P29*Q29*Config!$B$19 -> 0.0001710242
A30: 29 | B30: {YN_Q_MARKER} {OCCUPATION} {NAME}? | C30: {BE_EN} {NAME_EN} {OCCUPATION_EN}? | D30: ¿{NAME_ES} {COP_ES} {OCCUPATION_ES}? | F30: 3sg - Name | G30: 1-cop | H30: PRS | I30: Simple | K30: Active | L30: aff | M30: Yes/no question | N30: Is occupation | O30: Is Mateo a fireman? | P30: =PRODUCT(_xlfn.XLOOKUP(F30,Config!$A$2:$A$15,Config!$B$2:$B$15),_xlfn.XLOOKUP(G30,Config!$C$2:$C$7,Config!$D$2:$D$7),_xlfn.XLOOKUP(H30,Config!$E$2:$E$5,Config!$F$2:$F$5),_xlfn.XLOOKUP(I30,Config!$G$2:$G$3,Config!$H$2:$H$3),_xlfn.XLOOKUP(J30,Config!$I$2:$I$3,Config!$J$2:$J$3),_xlfn.XLOOKUP(K30,Config!$K$2:$K$3,Config!$L$2:$L$3),_xlfn.XLOOKUP(L30,Config!$M$2:$M$3,Config!$N$2:$N$3),_xlfn.XLOOKUP(M30,Config!$O$2:$O$6,Config!$P$2:$P$6)) -> 0.00069813735 | Q30: 1 | R30: =P30*Q30*Config!$B$19 -> 0.0005130726
A31: 30 | B31: {YN_Q_MARKER} {ADJ} {NAME}? | C31: {BE_EN} {NAME_EN} {ADJ_EN}? | D31: ¿{NAME_ES} {COP_ES} {ADJ_ES}? | F31: 3sg - Name | G31: 1-cop | H31: PRS | I31: Simple | K31: Active | L31: aff | M31: Yes/no question | N31: None | O31: Is Carlos kind? | P31: =PRODUCT(_xlfn.XLOOKUP(F31,Config!$A$2:$A$15,Config!$B$2:$B$15),_xlfn.XLOOKUP(G31,Config!$C$2:$C$7,Config!$D$2:$D$7),_xlfn.XLOOKUP(H31,Config!$E$2:$E$5,Config!$F$2:$F$5),_xlfn.XLOOKUP(I31,Config!$G$2:$G$3,Config!$H$2:$H$3),_xlfn.XLOOKUP(J31,Config!$I$2:$I$3,Config!$J$2:$J$3),_xlfn.XLOOKUP(K31,Config!$K$2:$K$3,Config!$L$2:$L$3),_xlfn.XLOOKUP(L31,Config!$M$2:$M$3,Config!$N$2:$N$3),_xlfn.XLOOKUP(M31,Config!$O$2:$O$6,Config!$P$2:$P$6)) -> 0.00069813735 | Q31: 1 | R31: =P31*Q31*Config!$B$19 -> 0.0005130726
A32: 31 | B32: {YN_Q_MARKER} {ADJ} {NP}? | C32: {BE_EN} {NP_EN} {ADJ_EN}? | D32: ¿{NP_ES} {COP_ES} {ADJ_ES}? | E32: Yes/no attributive question. | F32: 3sg - Noun | G32: 1-cop | H32: PRS | I32: Simple | K32: Active | L32: aff | M32: Yes/no question | N32: None | O32: Is the house big? | P32: =PRODUCT(_xlfn.XLOOKUP(F32,Config!$A$2:$A$15,Config!$B$2:$B$15),_xlfn.XLOOKUP(G32,Config!$C$2:$C$7,Config!$D$2:$D$7),_xlfn.XLOOKUP(H32,Config!$E$2:$E$5,Config!$F$2:$F$5),_xlfn.XLOOKUP(I32,Config!$G$2:$G$3,Config!$H$2:$H$3),_xlfn.XLOOKUP(J32,Config!$I$2:$I$3,Config!$J$2:$J$3),_xlfn.XLOOKUP(K32,Config!$K$2:$K$3,Config!$L$2:$L$3),_xlfn.XLOOKUP(L32,Config!$M$2:$M$3,Config!$N$2:$N$3),_xlfn.XLOOKUP(M32,Config!$O$2:$O$6,Config!$P$2:$P$6)) -> 0.00069813735 | Q32: 1 | R32: =P32*Q32*Config!$B$19 -> 0.0005130726
A33: 32 | B33: {YN_Q_MARKER} {ADJ} {NP}? | C33: {BE_EN} {NP_EN} {ADJ_EN}? | D33: ¿{COP_ES} {ADJ_ES} {NP_ES}? | E33: Yes/no attributive question. Variant for Spanish. | F33: 3sg - Noun | G33: 1-cop | H33: PRS | I33: Simple | K33: Active | L33: aff | M33: Yes/no question | N33: None | O33: Is the house big? | P33: =PRODUCT(_xlfn.XLOOKUP(F33,Config!$A$2:$A$15,Config!$B$2:$B$15),_xlfn.XLOOKUP(G33,Config!$C$2:$C$7,Config!$D$2:$D$7),_xlfn.XLOOKUP(H33,Config!$E$2:$E$5,Config!$F$2:$F$5),_xlfn.XLOOKUP(I33,Config!$G$2:$G$3,Config!$H$2:$H$3),_xlfn.XLOOKUP(J33,Config!$I$2:$I$3,Config!$J$2:$J$3),_xlfn.XLOOKUP(K33,Config!$K$2:$K$3,Config!$L$2:$L$3),_xlfn.XLOOKUP(L33,Config!$M$2:$M$3,Config!$N$2:$N$3),_xlfn.XLOOKUP(M33,Config!$O$2:$O$6,Config!$P$2:$P$6)) -> 0.00069813735 | Q33: 1 | R33: =P33*Q33*Config!$B$19 -> 0.0005130726
A34: 33 | B34: {YN_Q_MARKER} {ADJ} {NP_PL}? | C34: {BE_EN} {NP_PL_EN} {ADJ_EN}? | D34: ¿{COP_ES} {NP_PL_ES} {ADJ_ES}? | E34: Yes/no attributive question. | F34: 3pl - Noun def | G34: 1-cop | H34: PRS | I34: Simple | K34: Active | L34: aff | M34: Yes/no question | N34: None | O34: Are the houses big? | P34: =PRODUCT(_xlfn.XLOOKUP(F34,Config!$A$2:$A$15,Config!$B$2:$B$15),_xlfn.XLOOKUP(G34,Config!$C$2:$C$7,Config!$D$2:$D$7),_xlfn.XLOOKUP(H34,Config!$E$2:$E$5,Config!$F$2:$F$5),_xlfn.XLOOKUP(I34,Config!$G$2:$G$3,Config!$H$2:$H$3),_xlfn.XLOOKUP(J34,Config!$I$2:$I$3,Config!$J$2:$J$3),_xlfn.XLOOKUP(K34,Config!$K$2:$K$3,Config!$L$2:$L$3),_xlfn.XLOOKUP(L34,Config!$M$2:$M$3,Config!$N$2:$N$3),_xlfn.XLOOKUP(M34,Config!$O$2:$O$6,Config!$P$2:$P$6)) -> 0.00026180151 | Q34: 1 | R34: =P34*Q34*Config!$B$19 -> 0.00019240222
A35: 34 | B35: {YN_Q_MARKER} {ADJ} {NP_PL}? | C35: {BE_EN} {NP_PL_INDEF_EN} {ADJ_EN}? | D35: ¿{COP_ES} {NP_PL_ES} {ADJ_ES}? | E35: Yes/no attributive question. | F35: 3pl - Noun indef | G35: 1-cop | H35: PRS | I35: Simple | K35: Active | L35: aff | M35: Yes/no question | N35: None | O35: Are mice small? | P35: =PRODUCT(_xlfn.XLOOKUP(F35,Config!$A$2:$A$15,Config!$B$2:$B$15),_xlfn.XLOOKUP(G35,Config!$C$2:$C$7,Config!$D$2:$D$7),_xlfn.XLOOKUP(H35,Config!$E$2:$E$5,Config!$F$2:$F$5),_xlfn.XLOOKUP(I35,Config!$G$2:$G$3,Config!$H$2:$H$3),_xlfn.XLOOKUP(J35,Config!$I$2:$I$3,Config!$J$2:$J$3),_xlfn.XLOOKUP(K35,Config!$K$2:$K$3,Config!$L$2:$L$3),_xlfn.XLOOKUP(L35,Config!$M$2:$M$3,Config!$N$2:$N$3),_xlfn.XLOOKUP(M35,Config!$O$2:$O$6,Config!$P$2:$P$6)) -> 0.00026180151 | Q35: 1 | R35: =P35*Q35*Config!$B$19 -> 0.00019240222
A36: 35 | B36: {YN_Q_MARKER} {ADJ} {POSS_NP_PL_PRE}? | C36: {BE_EN} {POSS_NP_PL_EN} {ADJ_EN}? | D36: ¿{COP_ES} {ADJ_ES} {POSS_NP_PL_ES}? | E36: Yes/no question for an attributive predicate, possessed noun has preposed plural marker | F36: 3pl - Possessed noun | G36: 1-cop | H36: PRS | I36: Simple | K36: Active | L36: aff | M36: Yes/no question | N36: None | O36: Are my brothers kind? | P36: =PRODUCT(_xlfn.XLOOKUP(F36,Config!$A$2:$A$15,Config!$B$2:$B$15),_xlfn.XLOOKUP(G36,Config!$C$2:$C$7,Config!$D$2:$D$7),_xlfn.XLOOKUP(H36,Config!$E$2:$E$5,Config!$F$2:$F$5),_xlfn.XLOOKUP(I36,Config!$G$2:$G$3,Config!$H$2:$H$3),_xlfn.XLOOKUP(J36,Config!$I$2:$I$3,Config!$J$2:$J$3),_xlfn.XLOOKUP(K36,Config!$K$2:$K$3,Config!$L$2:$L$3),_xlfn.XLOOKUP(L36,Config!$M$2:$M$3,Config!$N$2:$N$3),_xlfn.XLOOKUP(M36,Config!$O$2:$O$6,Config!$P$2:$P$6)) -> 0.00026180151 | Q36: 1 | R36: =P36*Q36*Config!$B$19 -> 0.00019240222
A37: 36 | B37: {YN_Q_MARKER} {ADJ} {POSS_NP_PL_POST}? | C37: {BE_EN} {POSS_NP_PL_EN} {ADJ_EN}? | D37: ¿{COP_ES} {ADJ_ES} {POSS_NP_PL_ES}? | E37: Yes/no question for an attributive predicate, possessed noun has postposed plural marker | F37: 3pl - Possessed noun | G37: 1-cop | H37: PRS | I37: Simple | K37: Active | L37: aff | M37: Yes/no question | N37: None | O37: Are my brothers kind? | P37: =PRODUCT(_xlfn.XLOOKUP(F37,Config!$A$2:$A$15,Config!$B$2:$B$15),_xlfn.XLOOKUP(G37,Config!$C$2:$C$7,Config!$D$2:$D$7),_xlfn.XLOOKUP(H37,Config!$E$2:$E$5,Config!$F$2:$F$5),_xlfn.XLOOKUP(I37,Config!$G$2:$G$3,Config!$H$2:$H$3),_xlfn.XLOOKUP(J37,Config!$I$2:$I$3,Config!$J$2:$J$3),_xlfn.XLOOKUP(K37,Config!$K$2:$K$3,Config!$L$2:$L$3),_xlfn.XLOOKUP(L37,Config!$M$2:$M$3,Config!$N$2:$N$3),_xlfn.XLOOKUP(M37,Config!$O$2:$O$6,Config!$P$2:$P$6)) -> 0.00026180151 | Q37: 1 | R37: =P37*Q37*Config!$B$19 -> 0.00019240222
A38: 37 | B38: {YN_Q_MARKER} {ADJ} {POSS_NP}? | C38: {BE_EN} {POSS_NP_EN} {ADJ_EN}? | D38: ¿{POSS_NP_ES} {COP_ES} {ADJ_ES}? | E38: Yes/no question for an attributive predicate. | F38: 3sg - Possesed noun | G38: 1-cop | H38: PRS | I38: Simple | K38: Active | L38: aff | M38: Yes/no question | N38: None | O38: Is my wife kind? | P38: =PRODUCT(_xlfn.XLOOKUP(F38,Config!$A$2:$A$15,Config!$B$2:$B$15),_xlfn.XLOOKUP(G38,Config!$C$2:$C$7,Config!$D$2:$D$7),_xlfn.XLOOKUP(H38,Config!$E$2:$E$5,Config!$F$2:$F$5),_xlfn.XLOOKUP(I38,Config!$G$2:$G$3,Config!$H$2:$H$3),_xlfn.XLOOKUP(J38,Config!$I$2:$I$3,Config!$J$2:$J$3),_xlfn.XLOOKUP(K38,Config!$K$2:$K$3,Config!$L$2:$L$3),_xlfn.XLOOKUP(L38,Config!$M$2:$M$3,Config!$N$2:$N$3),_xlfn.XLOOKUP(M38,Config!$O$2:$O$6,Config!$P$2:$P$6)) -> 0.00069813735 | Q38: 1 | R38: =P38*Q38*Config!$B$19 -> 0.0005130726
A39: 38 | B39: {YN_Q_MARKER} {ADJ} {POSS_NP}? | C39: {BE_EN} {POSS_NP_EN} {ADJ_EN}? | D39: ¿{COP_ES} {ADJ_ES} {POSS_NP_ES}? | E39: Yes/no question for an attributive predicate. Variant for Spanish. | F39: 3sg - Possesed noun | G39: 1-cop | H39: PRS | I39: Simple | K39: Active | L39: aff | M39: Yes/no question | N39: None | O39: Is my wife kind? | P39: =PRODUCT(_xlfn.XLOOKUP(F39,Config!$A$2:$A$15,Config!$B$2:$B$15),_xlfn.XLOOKUP(G39,Config!$C$2:$C$7,Config!$D$2:$D$7),_xlfn.XLOOKUP(H39,Config!$E$2:$E$5,Config!$F$2:$F$5),_xlfn.XLOOKUP(I39,Config!$G$2:$G$3,Config!$H$2:$H$3),_xlfn.XLOOKUP(J39,Config!$I$2:$I$3,Config!$J$2:$J$3),_xlfn.XLOOKUP(K39,Config!$K$2:$K$3,Config!$L$2:$L$3),_xlfn.XLOOKUP(L39,Config!$M$2:$M$3,Config!$N$2:$N$3),_xlfn.XLOOKUP(M39,Config!$O$2:$O$6,Config!$P$2:$P$6)) -> 0.00069813735 | Q39: 1 | R39: =P39*Q39*Config!$B$19 -> 0.0005130726
A40: 39 | B40: {NEG_PRE} {ADJ} {NEG_SUF} {NAME}. | C40: {NAME_EN} {BE_NEG_EN} {ADJ_EN}. | D40: {NAME_ES} {COP_NEG_ES} {ADJ_ES}. | F40: 3sg - Name | G40: 1-cop | H40: PRS | I40: Simple | K40: Active | L40: neg | M40: Statement | N40: None | O40: Carlos is not kind | P40: =PRODUCT(_xlfn.XLOOKUP(F40,Config!$A$2:$A$15,Config!$B$2:$B$15),_xlfn.XLOOKUP(G40,Config!$C$2:$C$7,Config!$D$2:$D$7),_xlfn.XLOOKUP(H40,Config!$E$2:$E$5,Config!$F$2:$F$5),_xlfn.XLOOKUP(I40,Config!$G$2:$G$3,Config!$H$2:$H$3),_xlfn.XLOOKUP(J40,Config!$I$2:$I$3,Config!$J$2:$J$3),_xlfn.XLOOKUP(K40,Config!$K$2:$K$3,Config!$L$2:$L$3),_xlfn.XLOOKUP(L40,Config!$M$2:$M$3,Config!$N$2:$N$3),_xlfn.XLOOKUP(M40,Config!$O$2:$O$6,Config!$P$2:$P$6)) -> 0.00049280283 | Q40: 1 | R40: =P40*Q40*Config!$B$19 -> 0.00036216889
A41: 40 | B41: {NEG_PRE} {ADJ} {NEG_SUF} {NP}. | C41: {NP_EN} {BE_NEG_EN} {ADJ_EN}. | D41: {NP_ES} {COP_NEG_ES} {ADJ_ES}. | E41: Negative attributive predicate. | F41: 3sg - Noun | G41: 1-cop | H41: PRS | I41: Simple | K41: Active | L41: neg | M41: Statement | N41: None | O41: The house is not big. | P41: =PRODUCT(_xlfn.XLOOKUP(F41,Config!$A$2:$A$15,Config!$B$2:$B$15),_xlfn.XLOOKUP(G41,Config!$C$2:$C$7,Config!$D$2:$D$7),_xlfn.XLOOKUP(H41,Config!$E$2:$E$5,Config!$F$2:$F$5),_xlfn.XLOOKUP(I41,Config!$G$2:$G$3,Config!$H$2:$H$3),_xlfn.XLOOKUP(J41,Config!$I$2:$I$3,Config!$J$2:$J$3),_xlfn.XLOOKUP(K41,Config!$K$2:$K$3,Config!$L$2:$L$3),_xlfn.XLOOKUP(L41,Config!$M$2:$M$3,Config!$N$2:$N$3),_xlfn.XLOOKUP(M41,Config!$O$2:$O$6,Config!$P$2:$P$6)) -> 0.00049280283 | Q41: 1 | R41: =P41*Q41*Config!$B$19 -> 0.00036216889
A42: 41 | B42: {NEG_PRE} {ADJ} {NEG_SUF} {NP_PL}. | C42: {NP_PL_EN} {BE_NEG_EN} {ADJ_EN}. | D42: {NP_PL_ES} {COP_NEG_ES} {ADJ_ES}. | E42: Negative attributive predicate. | F42: 3pl - Noun def | G42: 1-cop | H42: PRS | I42: Simple | K42: Active | L42: neg | M42: Statement | N42: None | O42: The houses are not big. | P42: =PRODUCT(_xlfn.XLOOKUP(F42,Config!$A$2:$A$15,Config!$B$2:$B$15),_xlfn.XLOOKUP(G42,Config!$C$2:$C$7,Config!$D$2:$D$7),_xlfn.XLOOKUP(H42,Config!$E$2:$E$5,Config!$F$2:$F$5),_xlfn.XLOOKUP(I42,Config!$G$2:$G$3,Config!$H$2:$H$3),_xlfn.XLOOKUP(J42,Config!$I$2:$I$3,Config!$J$2:$J$3),_xlfn.XLOOKUP(K42,Config!$K$2:$K$3,Config!$L$2:$L$3),_xlfn.XLOOKUP(L42,Config!$M$2:$M$3,Config!$N$2:$N$3),_xlfn.XLOOKUP(M42,Config!$O$2:$O$6,Config!$P$2:$P$6)) -> 0.00018480106 | Q42: 1 | R42: =P42*Q42*Config!$B$19 -> 0.00013581333
A43: 42 | B43: {NEG_PRE} {ADJ} {NEG_SUF} {NP_PL}. | C43: {NP_PL_INDEF_EN} {BE_NEG_EN} {ADJ_EN}. | D43: {NP_PL_ES} {COP_NEG_ES} {ADJ_ES}. | E43: Negative attributive predicate. | F43: 3pl - Noun indef | G43: 1-cop | H43: PRS | I43: Simple | K43: Active | L43: neg | M43: Statement | N43: None | O43: Mice are not big. | P43: =PRODUCT(_xlfn.XLOOKUP(F43,Config!$A$2:$A$15,Config!$B$2:$B$15),_xlfn.XLOOKUP(G43,Config!$C$2:$C$7,Config!$D$2:$D$7),_xlfn.XLOOKUP(H43,Config!$E$2:$E$5,Config!$F$2:$F$5),_xlfn.XLOOKUP(I43,Config!$G$2:$G$3,Config!$H$2:$H$3),_xlfn.XLOOKUP(J43,Config!$I$2:$I$3,Config!$J$2:$J$3),_xlfn.XLOOKUP(K43,Config!$K$2:$K$3,Config!$L$2:$L$3),_xlfn.XLOOKUP(L43,Config!$M$2:$M$3,Config!$N$2:$N$3),_xlfn.XLOOKUP(M43,Config!$O$2:$O$6,Config!$P$2:$P$6)) -> 0.00018480106 | Q43: 1 | R43: =P43*Q43*Config!$B$19 -> 0.00013581333
A44: 43 | B44: {NEG_PRE} {ADJ} {NEG_SUF} {POSS_NP_PL_PRE}. | C44: {POSS_NP_PL_EN} {BE_NEG_EN} {ADJ_EN}. | D44: {POSS_NP_PL_ES} {COP_NEG_ES} {ADJ_ES}. | E44: Negative attributive predicate for possessed subject (preposed plural marker) | F44: 3pl - Possessed noun | G44: 1-cop | H44: PRS | I44: Simple | K44: Active | L44: neg | M44: Statement | N44: None | O44: My brothers are not kind. | P44: =PRODUCT(_xlfn.XLOOKUP(F44,Config!$A$2:$A$15,Config!$B$2:$B$15),_xlfn.XLOOKUP(G44,Config!$C$2:$C$7,Config!$D$2:$D$7),_xlfn.XLOOKUP(H44,Config!$E$2:$E$5,Config!$F$2:$F$5),_xlfn.XLOOKUP(I44,Config!$G$2:$G$3,Config!$H$2:$H$3),_xlfn.XLOOKUP(J44,Config!$I$2:$I$3,Config!$J$2:$J$3),_xlfn.XLOOKUP(K44,Config!$K$2:$K$3,Config!$L$2:$L$3),_xlfn.XLOOKUP(L44,Config!$M$2:$M$3,Config!$N$2:$N$3),_xlfn.XLOOKUP(M44,Config!$O$2:$O$6,Config!$P$2:$P$6)) -> 0.00018480106 | Q44: 1 | R44: =P44*Q44*Config!$B$19 -> 0.00013581333
A45: 44 | B45: {NEG_PRE} {ADJ} {NEG_SUF} {POSS_NP_PL_POST}. | C45: {POSS_NP_PL_EN} {BE_NEG_EN} {ADJ_EN}. | D45: {POSS_NP_PL_ES} {COP_NEG_ES} {ADJ_ES}. | E45: Negative attributive predicate for possessed subject (postposed plural marker) | F45: 3pl - Possessed noun | G45: 1-cop | H45: PRS | I45: Simple | K45: Active | L45: neg | M45: Statement | N45: None | O45: My brothers are not kind. | P45: =PRODUCT(_xlfn.XLOOKUP(F45,Config!$A$2:$A$15,Config!$B$2:$B$15),_xlfn.XLOOKUP(G45,Config!$C$2:$C$7,Config!$D$2:$D$7),_xlfn.XLOOKUP(H45,Config!$E$2:$E$5,Config!$F$2:$F$5),_xlfn.XLOOKUP(I45,Config!$G$2:$G$3,Config!$H$2:$H$3),_xlfn.XLOOKUP(J45,Config!$I$2:$I$3,Config!$J$2:$J$3),_xlfn.XLOOKUP(K45,Config!$K$2:$K$3,Config!$L$2:$L$3),_xlfn.XLOOKUP(L45,Config!$M$2:$M$3,Config!$N$2:$N$3),_xlfn.XLOOKUP(M45,Config!$O$2:$O$6,Config!$P$2:$P$6)) -> 0.00018480106 | Q45: 1 | R45: =P45*Q45*Config!$B$19 -> 0.00013581333
A46: 45 | B46: {NEG_PRE} {ADJ} {NEG_SUF} {POSS_NP}. | C46: {POSS_NP_EN} {BE_NEG_EN} {ADJ_EN}. | D46: {POSS_NP_ES} {COP_NEG_ES} {ADJ_ES}. | E46: Negative attributive predicate for possessed subject. | F46: 3sg - Possesed noun | G46: 1-cop | H46: PRS | I46: Simple | K46: Active | L46: neg | M46: Statement | N46: None | O46: My wife is not kind. | P46: =PRODUCT(_xlfn.XLOOKUP(F46,Config!$A$2:$A$15,Config!$B$2:$B$15),_xlfn.XLOOKUP(G46,Config!$C$2:$C$7,Config!$D$2:$D$7),_xlfn.XLOOKUP(H46,Config!$E$2:$E$5,Config!$F$2:$F$5),_xlfn.XLOOKUP(I46,Config!$G$2:$G$3,Config!$H$2:$H$3),_xlfn.XLOOKUP(J46,Config!$I$2:$I$3,Config!$J$2:$J$3),_xlfn.XLOOKUP(K46,Config!$K$2:$K$3,Config!$L$2:$L$3),_xlfn.XLOOKUP(L46,Config!$M$2:$M$3,Config!$N$2:$N$3),_xlfn.XLOOKUP(M46,Config!$O$2:$O$6,Config!$P$2:$P$6)) -> 0.00049280283 | Q46: 1 | R46: =P46*Q46*Config!$B$19 -> 0.00036216889
A47: 46 | B47: {V_INTR_IMP_PL}! | C47: {V_INTR_IMP_EN}! | D47: {V_INTR_IMP_USTEDES_ES}! | F47: 1pl | G47: 2-intr | H47: PRS | I47: Simple | J47: IMP | K47: Active | L47: aff | M47: Command | N47: None | O47: Let's dance | P47: =PRODUCT(_xlfn.XLOOKUP(F47,Config!$A$2:$A$15,Config!$B$2:$B$15),_xlfn.XLOOKUP(G47,Config!$C$2:$C$7,Config!$D$2:$D$7),_xlfn.XLOOKUP(H47,Config!$E$2:$E$5,Config!$F$2:$F$5),_xlfn.XLOOKUP(I47,Config!$G$2:$G$3,Config!$H$2:$H$3),_xlfn.XLOOKUP(J47,Config!$I$2:$I$3,Config!$J$2:$J$3),_xlfn.XLOOKUP(K47,Config!$K$2:$K$3,Config!$L$2:$L$3),_xlfn.XLOOKUP(L47,Config!$M$2:$M$3,Config!$N$2:$N$3),_xlfn.XLOOKUP(M47,Config!$O$2:$O$6,Config!$P$2:$P$6)) -> 0.00012654561 | Q47: 1 | R47: =P47*Q47*Config!$B$19 -> 9.3000447e-05
...

Sheet Sheet1
A1: id | B1: kek | C1: en | D1: es | E1: description | F1: Subject | G1: Transitivity | H1: Tense | I1: Aspect | J1: Mood | K1: Voice | L1: Polarity | M1: Q/S/C | N1: Modifier | O1: example_en | P1: p_value | Q1: variant_dist | R1: p_value_norm | S1: Notes
A2: 549 | B2: {NEG_PRE} Aj {PLACE}-{AFFIX_PRONOUN} {NEG_SUF}. | C2: {SUBJ_PRONOUN_EN} {BE_EN} not from {PLACE_EN}. | D2: {SUBJ_PRONOUN_ES} no {V_SER_ES} de {PLACE_ES}. | E2: Negated origin predicate. | F2: 1sg | G2: 1-cop | H2: PRS | I2: Simple | J2: ind | K2: Active | L2: neg | M2: Statement | S2: Placeholders: existing; New placeholders: none. SAFE: Unknown until negation for 'Aj PLACE-AFFIX' predicate is validated in Q'eqchi generator.
A3: 550 | B3: {NEG_PRE} {OCCUPATION}-{AFFIX_PRONOUN} {NEG_SUF}. | C3: {SUBJ_PRONOUN_EN} {BE_EN} not {OCCUPATION_EN}. | D3: {SUBJ_PRONOUN_ES} no {V_SER_ES} {OCCUPATION_ES}. | E3: Negated occupation predicate. | F3: 1sg | G3: 1-cop | H3: PST | I3: Simple | J3: ind | K3: Active | L3: neg | M3: Statement | S3: Placeholders: existing; New placeholders: none. SAFE: Likely if negation wrapper works for predicate-noun + affix pronoun; validate.
A4: 551 | B4: Aj {PLACE}-{AFFIX_PRONOUN}, k'ut {NEG_PRE} {OCCUPATION}-{AFFIX_PRONOUN} {NEG_SUF}. | C4: {SUBJ_PRONOUN_EN} {BE_EN} from {PLACE_EN}, but {SUBJ_PRONOUN_EN} {BE_EN} not {OCCUPATION_EN}. | D4: {SUBJ_PRONOUN_ES} {V_SER_ES} de {PLACE_ES}, pero no {V_SER_ES} {OCCUPATION_ES}. | E4: Coordinate/contrast: origin + neg occupation. | F4: 1sg | G4: 1-cop | H4: FUT | I4: Simple | J4: ind | K4: Active | M4: Statement | S4: Placeholders: existing; New placeholders: none. SAFE: No (Polarity mix; validate conjunction + negation composition). (Mixed polarity across clauses.)
A5: 552 | B5: {NEG_PRE} Aj {PLACE}-{AFFIX_PRONOUN} {NEG_SUF}, k'ut {OCCUPATION}-{AFFIX_PRONOUN}. | C5: {SUBJ_PRONOUN_EN} {BE_EN} not from {PLACE_EN}, but {SUBJ_PRONOUN_EN} {BE_EN} {OCCUPATION_EN}. | D5: {SUBJ_PRONOUN_ES} no {V_SER_ES} de {PLACE_ES}, pero {V_SER_ES} {OCCUPATION_ES}. | E5: Coordinate/contrast: neg origin + occupation. | F5: 1sg | G5: 1-cop | H5: PRS | I5: Simple | J5: ind | K5: Active | M5: Statement | S5: Placeholders: existing; New placeholders: none. SAFE: No (needs validated neg origin + contrast conjunction composition). (Mixed polarity across clauses.)
A6: 553 | B6: K'o {OBJECT} chi {PLACE}. | C6: There is {OBJECT_EN} in {PLACE_EN}. | D6: Hay {OBJECT_ES} en {PLACE_ES}. | E6: Existential: singular object in place. | F6: 3sg | G6: exist | H6: PST | I6: Simple | J6: ind | K6: Active | L6: aff | M6: Statement | S6: SAFE: Yes. Uses existing existential construction (k'o). Placeholders: existing.
A7: 554 | B7: K'o {OBJECT_PL} chi {PLACE}. | C7: There are {OBJECT_PL_EN} in {PLACE_EN}. | D7: Hay {OBJECT_PL_ES} en {PLACE_ES}. | E7: Existential: plural objects in place. | F7: 3pl | G7: exist | H7: FUT | I7: Simple | J7: ind | K7: Active | L7: aff | M7: Statement | S7: SAFE: Yes. Uses existing existential construction (k'o). Placeholders: existing.
A8: 555 | B8: {VERB_INTR}{AFFIX_PRONOUN} junel chi {TIME_UNIT}. | C8: {SUBJ_PRONOUN_EN} {VERB_EN} every {TIME_UNIT_EN}. | D8: {SUBJ_PRONOUN_ES} {VERB_ES} cada {TIME_UNIT_ES}. | E8: Habitual intransitive action. | F8: 1sg | G8: intr | H8: PRS | I8: Simple | J8: ind | K8: Active | L8: aff | M8: Statement | S8: SAFE: Yes. Habitual frame with junel chi. Placeholders: existing.
A9: 556 | B9: {VERB_TR}{AFFIX_PRONOUN} {OBJECT} junel chi {TIME_UNIT}. | C9: {SUBJ_PRONOUN_EN} {VERB_EN} {OBJECT_EN} every {TIME_UNIT_EN}. | D9: {SUBJ_PRONOUN_ES} {VERB_ES} {OBJECT_ES} cada {TIME_UNIT_ES}. | E9: Habitual transitive action. | F9: 1sg | G9: tr | H9: PST | I9: Simple | J9: ind | K9: Active | L9: aff | M9: Statement | S9: SAFE: Yes. Habitual frame with junel chi. Placeholders: existing.
A10: 557 | B10: {VERB_INTR}{AFFIX_PRONOUN} chi {PLACE}. | C10: {SUBJ_PRONOUN_EN} {VERB_EN} to {PLACE_EN}. | D10: {SUBJ_PRONOUN_ES} {VERB_ES} a {PLACE_ES}. | E10: Motion to place (intransitive). | F10: 1sg | G10: intr | H10: FUT | I10: Simple | J10: ind | K10: Active | L10: aff | M10: Statement | S10: SAFE: Yes. Simple motion-to-place. Placeholders: existing.
A11: 558 | B11: Aj {PLACE}-{AFFIX_PRONOUN}. {OCCUPATION}{AFFIX_PRONOUN}. | C11: {SUBJ_PRONOUN_EN} {BE_EN} from {PLACE_EN}. {SUBJ_PRONOUN_EN} {BE_EN} {OCCUPATION_EN}. | D11: {SUBJ_PRONOUN_ES} {V_SER_ES} de {PLACE_ES}. {SUBJ_PRONOUN_ES} {V_SER_ES} {OCCUPATION_ES}. | E11: Two-sentence pair: origin + occupation (same pronoun subject). | F11: 1sg | G11: PAIR-2S | H11: PRS | I11: Simple | K11: Active | L11: aff | M11: Statement | Q11: 1
A12: 559 | B12: Aj {PLACE} {NAME}. {SUBJ_PRONOUN} {OCCUPATION}. | C12: {NAME_EN} {BE_EN} from {PLACE_EN}. {SUBJ_PRONOUN_EN} {BE_EN} {OCCUPATION_EN}. | D12: {NAME_ES} {V_SER_ES} de {PLACE_ES}. {SUBJ_PRONOUN_ES} {V_SER_ES} {OCCUPATION_ES}. | E12: Two-sentence pair: origin (name) + occupation (pronoun coref to name). | F12: 3sg - Name | G12: PAIR-2S | H12: PRS | I12: Simple | K12: Active | L12: aff | M12: Statement | Q12: 1 | S12: Coreference relies on generator choosing 3sg pronoun in sentence 2; gender may be random unless tied to NAME metadata.
A13: 560 | B13: {OCCUPATION} {NAME}. Aj {PLACE} {NAME}. | C13: {NAME_EN} {BE_EN} {OCCUPATION_EN}. {NAME_EN} {BE_EN} from {PLACE_EN}. | D13: {NAME_ES} {V_SER_ES} {OCCUPATION_ES}. {NAME_ES} {V_SER_ES} de {PLACE_ES}. | E13: Two-sentence pair: occupation + origin (repeat name for strict coreference). | F13: 3sg - Name | G13: PAIR-2S | H13: PRS | I13: Simple | K13: Active | L13: aff | M13: Statement | Q13: 1
A14: 561 | B14: {EXIST} {NP} {WITH_PRON_KEK}. {ADJ} {NP}. | C14: {SUBJ_PRONOUN_EN} {V_POSS_TR_EN} {THEME_NP_INDEF_EN}. {NP_DEF_EN} {BE_EN} {ADJ_EN}. | D14: {SUBJ_PRONOUN_ES} {V_POSS_TR_ES} {THEME_NP_INDEF_ES}. {NP_DEF_ES} {COP_ES} {ADJ_ES}. | E14: Two-sentence pair: possession + anaphoric attribute of the possessed item. | F14: 1sg | G14: PAIR-2S | H14: PRS | I14: Simple | K14: Active | L14: aff | M14: Statement | O14: I have a house. The house is big. | Q14: 1 | S14: Requires NEW placeholders: NP_DEF_EN, NP_DEF_ES (definite anaphoric NP built from the same NP selected in sentence 1). KEK can reuse {NP} because subject-article insertion already yields 'li' for subjects.
A15: 562 | B15: {NAME} {V_TR} {THEME_NP}. {ADJ} {THEME_NP}. | C15: {NAME_EN} {V_TR_EN} {THEME_NP_INDEF_EN}. {THEME_NP_DEF_EN} {BE_EN} {ADJ_EN}. | D15: {NAME_ES} {V_TR_ES} {THEME_NP_INDEF_ES}. {THEME_NP_DEF_ES} {COP_ES} {ADJ_ES}. | E15: Two-sentence pair: transitive event + anaphoric attribute of theme (same theme). | F15: 3sg - Name | G15: PAIR-2S | H15: PRS | I15: Simple | K15: Active | L15: aff | M15: Statement | O15: Juan sees a dog. The dog is small. | Q15: 1 | S15: Requires NEW placeholders: THEME_NP_DEF_EN, THEME_NP_DEF_ES (definite anaphoric theme NP). Ensure {THEME_NP} reuse across both sentences keeps KEK coreference.
A16: 563 | B16: {NAME} {V_TR} {THEME_NP}. {ADJ}{AFFIX_PRONOUN}. | C16: {NAME_EN} {V_TR_EN} {THEME_NP_INDEF_EN}. {SUBJ_PRONOUN_EN} {BE_EN} {ADJ_EN}. | D16: {NAME_ES} {V_TR_ES} {THEME_NP_INDEF_ES}. {SUBJ_PRONOUN_ES} {COP_ES} {ADJ_ES}. | E16: Two-sentence pair: transitive event + subject attribute (pronoun coref to name). | F16: 3sg - Name | G16: PAIR-2S | H16: PRS | I16: Simple | K16: Active | L16: aff | M16: Statement | O16: Juan helps a woman. He is kind. | Q16: 1 | S16: Coreference relies on sentence 2 pronoun matching NAME; consider tying pronoun gender to NAME metadata if you want deterministic he/she.
A17: 564 | B17: {ADV} {V_INTR} {SUBJ_PRONOUN}. {ADJ}{AFFIX_PRONOUN}. | C17: {SUBJ_PRONOUN_EN} {V_INTR_EN} {ADV_EN}. {SUBJ_PRONOUN_EN} {BE_EN} {ADJ_EN}. | D17: {SUBJ_PRONOUN_ES} {V_INTR_ES} {ADV_ES}. {SUBJ_PRONOUN_ES} {COP_ES} {ADJ_ES}. | E17: Two-sentence pair: intransitive action (with adverb) + attribute (same pronoun subject). | F17: 3sg | G17: PAIR-2S | H17: PRS | I17: Simple | K17: Active | L17: aff | M17: Statement | O17: He runs quickly. He is tired. | Q17: 1 | S17: Check KEK adverb placement conventions; current pattern mirrors existing 'ADV + V_INTR + SUBJECT' templates used with possessed NPs.

Sheet Config
A1: person | B1: p_person | C1: transitivity | D1: p_transitivity | E1: tense | F1: p_tense | G1: aspect | H1: p_aspect | I1: mood | J1: p_mood | K1: voice | L1: p_voice | M1: polarity | N1: p_polarity | O1: clause_type | P1: p_clause
A2: 1sg | B2: =0.22*0.64 -> 0.1408 | C2: 1-cop | D2: 0.18 | E2: none | F2: 0.05 | G2: Simple | H2: 0.7 | J2: 0.9 | K2: Active | L2: 0.93 | M2: aff | N2: 0.85 | O2: Command | P2: 0.15
A3: 2sg | B3: =0.19*0.64 -> 0.1216 | C3: 2-intr | D3: 0.35 | E3: PRS | F3: 0.55 | G3: PROG | H3: 0.3 | I3: IMP | J3: 0.1 | K3: Passive | L3: 0.07 | M3: neg | N3: 0.15 | O3: Statement | P3: 0.6
A4: 3sg | B4: =0.59*0.64*1/4 -> 0.0944 | C4: 3-tr | D4: 0.27 | E4: FUT | F4: 0.2 | O4: Yes/No question | P4: 0.15
A5: 3sg - Name | B5: =0.59*0.64*1/4 -> 0.0944 | C5: 4-tr-have | D5: 0.07 | E5: PST | F5: 0.2 | O5: When question | P5: 0.05
A6: 3sg - Noun | B6: =0.59*0.64*1/4 -> 0.0944 | C6: 5-ditr | D6: 0.09 | O6: Where question | P6: 0.05
A7: 3sg - Possesed noun | B7: =0.59*0.64*1/4 -> 0.0944 | C7: 6-exist | D7: 0.04
A8: 1pl | B8: =0.22*0.36 -> 0.0792
A9: 2pl | B9: =0.19*0.36 -> 0.0684
A10: 3pl | B10: =0.59*0.36*1/6 -> 0.0354
A11: 3pl - Noun def | B11: =0.59*0.36*1/6 -> 0.0354
A12: 3pl - Noun def with attribute | B12: =0.59*0.36*1/6 -> 0.0354
A13: 3pl - Noun indef | B13: =0.59*0.36*1/6 -> 0.0354
A14: 3pl - Noun indef with numeral | B14: =0.59*0.36*1/6 -> 0.0354
A15: 3pl - Possessed noun | B15: =0.59*0.36*1/6 -> 0.0354
A18: Sum of all p_ | B18: =SUM(full_list!P:P) -> 1.360699
A19: Normalization | B19: =1/B18 -> 0.73491642

Sheet Medical
A1: id | B1: kek | C1: en | D1: es | E1: description | F1: example_en
A2: M1 | C2: My {BODY_PART} hurts. | D2: Me duele el/la {BODY_PART}. | E2: Patient Self-Description | F2: My knee hurts.
A3: M2 | C3: I have pain in my {BODY_PART}. | D3: Tengo dolor en mi {BODY_PART}. | E3: Patient Self-Description | F3: I have pain in my shoulder.
A4: M3 | C4: There’s a strange feeling in my {BODY_PART}. | D4: Siento una sensación extraña en mi {BODY_PART}. | E4: Patient Self-Description | F4: There’s a strange feeling in my arm.
A5: M4 | C5: My {BODY_PART} feels numb. | D5: Mi {BODY_PART} está entumecido/a. | E5: Patient Self-Description | F5: My hand feels numb.
A6: M5 | C6: My {BODY_PART} tingles. | D6: Siento hormigueo en mi {BODY_PART}. | E6: Patient Self-Description | F6: My fingers tingle.
A7: M6 | C7: My {BODY_PART} is swollen. | D7: Mi {BODY_PART} está hinchado/a. | E7: Patient Self-Description | F7: My ankle is swollen.
A8: M7 | C8: I can’t move my {BODY_PART}. | D8: No puedo mover mi {BODY_PART}. | E8: Patient Self-Description | F8: I can’t move my wrist.
A9: M8 | C9: I injured my {BODY_PART}. | D9: Me lastimé el/la {BODY_PART}. | E9: Patient Self-Description | F9: I injured my back.
A10: M9 | C10: My right {BODY_PART} feels weaker than the left. | D10: Mi {BODY_PART} derecho/a se siente más débil que el izquierdo/a. | E10: Patient Self-Description | F10: My right leg feels weaker than the left.
A11: M10 | C11: There’s a lump on my {BODY_PART}. | D11: Tengo un bulto en mi {BODY_PART}. | E11: Patient Self-Description | F11: There’s a lump on my neck.
A12: M11 | C12: Where exactly does your {BODY_PART} hurt? | D12: ¿Dónde exactamente le duele el/la {BODY_PART}? | E12: Doctor Question | F12: Where exactly does your abdomen hurt?
A13: M12 | C13: How long has your {BODY_PART} been hurting? | D13: ¿Desde cuándo le duele el/la {BODY_PART}? | E13: Doctor Question | F13: How long has your shoulder been hurting?
... A42: M41 | C42: My {BODY_PART} is healing. | D42: Mi {BODY_PART} se está curando. | E42: Patient Self-Description | F42: My wound is healing.
